Workbook

Sheet Getting Started - FAQ
A1: Getting started and FAQ
A3: Sales Invoices, IR35 and VAT
A4: IR35 Status: Enter Y or N in the yellow IR35 question box (cell E9).
A6: VAT Status: Enter Y or N in the yellow VAT question box. If you are using the VAT flat rate scheme then enter the scheme percentage into cell E12 on Month 1. Please contact your Accountant if you require further information about the Flat Rate VAT Scheme.
A8: Sales - enter your gross (i.e. including VAT if applicable) figure into the gross column. If you entered either Y or N in the IR35 question box, the other entries will be completed automatically for you.
A10: Banked Receipts
A11: Opening Bank Balances: Enter the opening bank balances only in cells K10 and K11 of Month 1. These balances should be taken from your last Company accounts (not applicable for first company year).
A13: The bankings section is used to record money received into the company bank accounts as follows:
A14: From Sales - money you receive from your agent or client.
A15: Interest Received on Current Account - interest received on the current account.
A16: Other Bankings - other money paid into the Company current account for example refunds, loans from the director to the company, etc.
A17: Transfers From Deposit Account - transfers you make back into your current account from the deposit account.
... A48: If you have any questions relating to the completion of your spreadsheet please do not hesitate to contact your Accountant.

Sheet Example
A2: Company name Ltd
A4: Month | C4: 42095
A7: Sales Invoices | I7: Bankings
A9: Does this months income fall within IR35? (Y/N/both) | E9: n | F9: =IF(E9="Both","enter sales invoices manually at row 30 onwards",0) -> 0
I10: Opening Bank Balance: | J10: Current Account | K10: 0
A11: Is the Company VAT registered (Y/N) | E11: y | I11: (if overdrawn enter a | J11: Deposit Account | K11: 0
A12: VAT Flat rate scheme percentage (leave blank or zero if not using flat rate scheme) | E12: 0 | I12: negative figure)
L13: Interest | N13: Transfers | O13: Interest
C14: Inv | K14: From | L14: Received on | N14: From | O14: Received on
A15: Date | B15: Details | C15: No | D15: IR35 | E15: Non IR35 | F15: Gross | G15: VAT | I15: Date | J15: Details | K15: Sales | L15: Current Account | M15: Other bankings | N15: Deposit Account | O15: Deposit Account
C16: Balance b/f | D16: 0 | E16: 0 | F16: 0 | G16: 0 | J16: Bal b/f
A17: 42101 | B17: First Agency Ltd | C17: 25 | E17: =F17-G17 -> 5500 | F17: 6600 | G17: =F17*1/6 -> 1100 | I17: 42113 | J17: First Agency | K17: 6600
A18: 42103 | B18: First Agency Ltd | C18: 26 | E18: =F18-G18 -> 4500 | F18: 5400 | G18: =F18*1/6 -> 900 | I18: 42120 | J18: Interest Received | L18: 7.5
D19: 0 | E19: 0 | G19: =F19*1/6 -> 0 | I19: 42121 | J19: Trf from Dep Ac | N19: 2000
A20: 42109 | B20: Inv 27 - raised without VAT | C20: Z27 | D20: 0 | E20: =F20-G20 -> 2500 | F20: 2500 | I20: 42122 | J20: Int on Dep Ac | O20: 16
A21: 42124 | B21: VAT Only Invoice for Inv 27 | C21: V28 | D21: 0 | F21: 500 | G21: 500
D22: =IF(E9="y",F22-G22,0) -> 0 | E22: =IF(E9="y",,F22-G22) -> 0 | F22: 0 | G22: =F22*1/6 -> 0
D23: =IF(E9="y",F23-G23,0) -> 0 | E23: =IF(E9="y",,F23-G23) -> 0 | G23: =F23*1/6 -> 0
D24: =IF(E9="y",F24-G24,0) -> 0 | E24: =IF(E9="y",,F24-G24) -> 0 | F24: 0 | G24: =F24*1/6 -> 0
D25: =IF(E9="y",F25-G25,0) -> 0 | E25: =IF(E9="y",,F25-G25) -> 0 | G25: =F25*1/6 -> 0
D26: =IF(E9="y",F26-G26,0) -> 0 | E26: =IF(E9="y",,F26-G26) -> 0 | G26: =F26*1/6 -> 0
D27: =IF(E9="y",F27-G27,0) -> 0 | E27: =IF(E9="y",,F27-G27) -> 0 | G27: =F27*1/6 -> 0
D28: =IF(E9="y",F28-G28,0) -> 0 | E28: =IF(E9="y",,F28-G28) -> 0 | G28: =F28*1/6 -> 0
D29: =IF(E9="y",F29-G29,0) -> 0 | E29: =IF(E9="y",,F29-G29) -> 0 | F29: 0 | G29: =F29*1/6 -> 0
B30: =IF(E9="Both","Enter manual values here",0) -> 0 | E30: 0 | F30: 0 | G30: =F30*1/6 -> 0
D31: 0 | F31: 0 | G31: =F31*1/6 -> 0
D32: 0 | F32: 0 | G32: =F32*1/6 -> 0
D33: 0 | F33: 0 | G33: =F33*1/6 -> 0
G34: =F34*1/6 -> 0
G35: =F35*1/6 -> 0
G36: =F36*1/6 -> 0
G37: =F37*1/6 -> 0
G38: =F38*1/6 -> 0
G39: =F39*1/6 -> 0
G40: =F40*1/6 -> 0
G41: =F41*1/6 -> 0
A42: Total | D42: =SUM(D17:D41) -> 0 | E42: =SUM(E17:E41) -> 12500 | F42: =SUM(F17:F41) -> 15000 | G42: =SUM(G17:G41) -> 2500 | I42: Total | K42: =SUM(K16:K41) -> 6600 | L42: =SUM(L16:L41) -> 7.5 | M42: =SUM(M16:M41) -> 0 | N42: =SUM(N16:N41) -> 2000 | O42: =SUM(O16:O41) -> 16
A43: C/fwd | D43: =SUM(D16:D41) -> 0 | E43: =SUM(E16:E41) -> 12500 | F43: =SUM(F16:F41) -> 15000 | G43: =SUM(G16:G41) -> 2500 | I43: C/fwd | K43: =SUM(K16:K41) -> 6600 | L43: =SUM(L16:L41) -> 7.5 | M43: =SUM(M16:M41) -> 0 | N43: =SUM(N16:N41) -> 2000 | O43: =SUM(O16:O41) -> 16
A63: Expenditure
I65: Travelling, | J65: Professional, Employers | R65: Assets Purchased: | T65: Subscriptions,
...

Sheet Nov 17
A1: 0
A2: Design-spectrum Limited
A4: Month | C4: 43040
A7: Sales Invoices | I7: Bankings - Receipts
A9: Does this months income fall within IR35? (Y/N/both) | E9: n
I10: Opening Bank Balance: | J10: Current Account | K10: 28875.31
A11: Is the Company VAT registered (Y/N) | E11: y | J11: Deposit Account | K11: 87011.69
A12: VAT Flat rate scheme percentage | E12: 0.165 | J12: (If overdrawn enter a negative figure)
A13: (leave blank or zero if not using flat rate scheme) | M13: Interest | O13: Transfers from | P13: Interest
L14: Sales Invoice | M14: Received on | O14: Deposit | P14: Received on
A15: Date | B15: Details | C15: Sales Invoice No | D15: IR35 | E15: Non IR35 | F15: Gross | G15: VAT | I15: Date | J15: Details | K15: Sales Invoice no | L15: Amount £ | M15: Current Account | N15: Other bankings | O15: Account | P15: Deposit Account
C16: Balance b/f | D16: 0 | E16: 0 | G16: 0 | J16: Balance b/f
B17: Raised in next month | D17: =IF(E$9="y",F17-G17,0) -> 0 | E17: =IF(E$9="n",F17-G17,0) -> 0 | G17: =IF(($E$11="n"),0,IF((LEFT(C17,1)="v"),F17,IF((LEFT(C17,1)="z"),0,F17*1/6))) -> 0 | J17: R S C S LTD | L17: 23100
D18: =IF(E$9="y",F18-G18,0) -> 0 | E18: =IF(E$9="n",F18-G18,0) -> 0 | G18: =IF(($E$11="n"),0,IF((LEFT(C18,1)="v"),F18,IF((LEFT(C18,1)="z"),0,F18*1/6))) -> 0 | P18: 1.43
D19: =IF(E$9="y",F19-G19,0) -> 0 | E19: =IF(E$9="n",F19-G19,0) -> 0 | G19: =IF(($E$11="n"),0,IF((LEFT(C19,1)="v"),F19,IF((LEFT(C19,1)="z"),0,F19*1/6))) -> 0
D20: =IF(E$9="y",F20-G20,0) -> 0 | E20: =IF(E$9="n",F20-G20,0) -> 0 | G20: =IF(($E$11="n"),0,IF((LEFT(C20,1)="v"),F20,IF((LEFT(C20,1)="z"),0,F20*1/6))) -> 0
D21: =IF(E$9="y",F21-G21,0) -> 0 | E21: =IF(E$9="n",F21-G21,0) -> 0 | G21: =IF(($E$11="n"),0,IF((LEFT(C21,1)="v"),F21,IF((LEFT(C21,1)="z"),0,F21*1/6))) -> 0
D22: =IF(E$9="y",F22-G22,0) -> 0 | E22: =IF(E$9="n",F22-G22,0) -> 0 | G22: =IF(($E$11="n"),0,IF((LEFT(C22,1)="v"),F22,IF((LEFT(C22,1)="z"),0,F22*1/6))) -> 0
D23: =IF(E$9="y",F23-G23,0) -> 0 | E23: =IF(E$9="n",F23-G23,0) -> 0 | G23: =IF(($E$11="n"),0,IF((LEFT(C23,1)="v"),F23,IF((LEFT(C23,1)="z"),0,F23*1/6))) -> 0
D24: =IF(E$9="y",F24-G24,0) -> 0 | E24: =IF(E$9="n",F24-G24,0) -> 0 | G24: =IF(($E$11="n"),0,IF((LEFT(C24,1)="v"),F24,IF((LEFT(C24,1)="z"),0,F24*1/6))) -> 0
D25: =IF(E$9="y",F25-G25,0) -> 0 | E25: =IF(E$9="n",F25-G25,0) -> 0 | G25: =IF(($E$11="n"),0,IF((LEFT(C25,1)="v"),F25,IF((LEFT(C25,1)="z"),0,F25*1/6))) -> 0
D26: =IF(E$9="y",F26-G26,0) -> 0 | E26: =IF(E$9="n",F26-G26,0) -> 0 | G26: =IF(($E$11="n"),0,IF((LEFT(C26,1)="v"),F26,IF((LEFT(C26,1)="z"),0,F26*1/6))) -> 0
D27: =IF(E$9="y",F27-G27,0) -> 0 | E27: =IF(E$9="n",F27-G27,0) -> 0 | G27: =IF(($E$11="n"),0,IF((LEFT(C27,1)="v"),F27,IF((LEFT(C27,1)="z"),0,F27*1/6))) -> 0
D28: =IF(E$9="y",F28-G28,0) -> 0 | E28: =IF(E$9="n",F28-G28,0) -> 0 | G28: =IF(($E$11="n"),0,IF((LEFT(C28,1)="v"),F28,IF((LEFT(C28,1)="z"),0,F28*1/6))) -> 0
D29: =IF(E$9="y",F29-G29,0) -> 0 | E29: =IF(E$9="n",F29-G29,0) -> 0 | G29: =IF(($E$11="n"),0,IF((LEFT(C29,1)="v"),F29,IF((LEFT(C29,1)="z"),0,F29*1/6))) -> 0
D30: =IF(E$9="y",F30-G30,0) -> 0 | E30: =IF(E$9="n",F30-G30,0) -> 0 | G30: =IF(($E$11="n"),0,IF((LEFT(C30,1)="v"),F30,IF((LEFT(C30,1)="z"),0,F30*1/6))) -> 0
... D40: =IF(E$9="y",F40-G40,0) -> 0 | E40: =IF(E$9="n",F40-G40,0) -> 0 | G40: =IF(($E$11="n"),0,IF((LEFT(C40,1)="v"),F40,IF((LEFT(C40,1)="z"),0,F40*1/6))) -> 0
B41: =IF(E9="Both","Enter manual values here",0) -> 0 | D41: =IF(E$9="y",F41-G41,0) -> 0 | E41: =IF(E$9="n",F41-G41,0) -> 0 | G41: =IF(($E$11="n"),0,IF((LEFT(C41,1)="v"),F41,IF((LEFT(C41,1)="z"),0,F41*1/6))) -> 0
D42: =IF(E$9="y",F42-G42,0) -> 0 | E42: =IF(E$9="n",F42-G42,0) -> 0 | G42: =IF(($E$11="n"),0,IF((LEFT(C42,1)="v"),F42,IF((LEFT(C42,1)="z"),0,F42*1/6))) -> 0
D43: =IF(E$9="y",F43-G43,0) -> 0 | E43: =IF(E$9="n",F43-G43,0) -> 0 | G43: =IF(($E$11="n"),0,IF((LEFT(C43,1)="v"),F43,IF((LEFT(C43,1)="z"),0,F43*1/6))) -> 0
D44: =IF(E$9="y",F44-G44,0) -> 0 | E44: =IF(E$9="n",F44-G44,0) -> 0 | G44: =IF(($E$11="n"),0,IF((LEFT(C44,1)="v"),F44,IF((LEFT(C44,1)="z"),0,F44*1/6))) -> 0
D45: =IF(E$9="y",F45-G45,0) -> 0 | E45: =IF(E$9="n",F45-G45,0) -> 0 | G45: =IF(($E$11="n"),0,IF((LEFT(C45,1)="v"),F45,IF((LEFT(C45,1)="z"),0,F45*1/6))) -> 0
D46: =IF(E$9="y",F46-G46,0) -> 0 | E46: =IF(E$9="n",F46-G46,0) -> 0 | G46: =IF(($E$11="n"),0,IF((LEFT(C46,1)="v"),F46,IF((LEFT(C46,1)="z"),0,F46*1/6))) -> 0
D47: =IF(E$9="y",F47-G47,0) -> 0 | E47: =IF(E$9="n",F47-G47,0) -> 0 | G47: =IF(($E$11="n"),0,IF((LEFT(C47,1)="v"),F47,IF((LEFT(C47,1)="z"),0,F47*1/6))) -> 0
D48: =IF(E$9="y",F48-G48,0) -> 0 | E48: =IF(E$9="n",F48-G48,0) -> 0 | G48: =IF(($E$11="n"),0,IF((LEFT(C48,1)="v"),F48,IF((LEFT(C48,1)="z"),0,F48*1/6))) -> 0
D49: =IF(E$9="y",F49-G49,0) -> 0 | E49: =IF(E$9="n",F49-G49,0) -> 0 | G49: =IF(($E$11="n"),0,IF((LEFT(C49,1)="v"),F49,IF((LEFT(C49,1)="z"),0,F49*1/6))) -> 0
D50: =IF(E$9="y",F50-G50,0) -> 0 | E50: =IF(E$9="n",F50-G50,0) -> 0 | G50: =IF(($E$11="n"),0,IF((LEFT(C50,1)="v"),F50,IF((LEFT(C50,1)="z"),0,F50*1/6))) -> 0
D51: =IF(E$9="y",F51-G51,0) -> 0 | E51: =IF(E$9="n",F51-G51,0) -> 0 | G51: =IF(($E$11="n"),0,IF((LEFT(C51,1)="v"),F51,IF((LEFT(C51,1)="z"),0,F51*1/6))) -> 0
D52: =IF(E$9="y",F52-G52,0) -> 0 | E52: =IF(E$9="n",F52-G52,0) -> 0 | G52: =IF(($E$11="n"),0,IF((LEFT(C52,1)="v"),F52,IF((LEFT(C52,1)="z"),0,F52*1/6))) -> 0
A53: Total | D53: =SUM(D17:D52) -> 0 | E53: =SUM(E17:E52) -> 0 | F53: =SUM(F17:F52) -> 0 | G53: =SUM(G17:G52) -> 0 | I53: Total | L53: =SUM(L17:L52) -> 23100 | M53: =SUM(M17:M52) -> 0 | N53: =SUM(N17:N52) -> 0 | O53: =SUM(O17:O52) -> 0 | P53: =SUM(P17:P52) -> 1.43
...

Sheet Dec 17
A1: 0
A2: ='Nov 17'!A2 -> Design-spectrum Limited
A4: Month | C4: ='Nov 17'!C4+31 -> 43071
A7: Sales Invoices | I7: Bankings - Receipts
A9: Does this months income fall within IR35? (Y/N/both) | E9: ='Nov 17'!E9 -> n | F9: =IF(E9="Both","enter sales invoices manually at row 30 onwards",0) -> 0
A11: Is the Company VAT registered (Y/N) | E11: ='Nov 17'!E11 -> y
A12: VAT Flat rate scheme percentage | E12: ='Nov 17'!E12 -> 0.165
A13: (leave blank or zero if not using flat rate scheme) | M13: Interest | O13: Transfers from | P13: Interest
L14: Sales Invoice | M14: Received on | O14: Deposit | P14: Received on
A15: Date | B15: Details | C15: Sales Invoice No | D15: IR35 | E15: Non IR35 | F15: Gross | G15: VAT | I15: Date | J15: Details | K15: Sales Invoice no | L15: Amount £ | M15: Current Account | N15: Other bankings | O15: Account | P15: Deposit Account
C16: Balance b/f | D16: ='Nov 17'!D54 -> 0 | E16: ='Nov 17'!E54 -> 0 | F16: ='Nov 17'!F54 -> 0 | G16: ='Nov 17'!G54 -> 0 | J16: Balance b/f | L16: ='Nov 17'!L54 -> 23100 | M16: ='Nov 17'!M54 -> 0 | N16: ='Nov 17'!N54 -> 0 | O16: ='Nov 17'!O54 -> 0 | P16: ='Nov 17'!P54 -> 1.43
B17: Invoice 30Oct-8Dec2017 | D17: =IF(E$9="y",F17-G17,0) -> 0 | E17: =IF(E$9="n",F17-G17,0) -> 16500 | F17: 19800 | G17: =IF(($E$11="n"),0,IF((LEFT(C17,1)="v"),F17,IF((LEFT(C17,1)="z"),0,F17*1/6))) -> 3300 | J17: MONEY MARKET MATURITY 40029090709255 | O17: 50488.86
B18: Invoice 11Dec-15Dec2017 | D18: =IF(E$9="y",F18-G18,0) -> 0 | E18: =IF(E$9="n",F18-G18,0) -> 2750 | F18: 3300 | G18: =IF(($E$11="n"),0,IF((LEFT(C18,1)="v"),F18,IF((LEFT(C18,1)="z"),0,F18*1/6))) -> 550 | J18: GROSS INTEREST TO 03DEC2017 FOR ACCOUNT 400290 90709255 | M18: 66.53 | P18: -66.53
D19: =IF(E$9="y",F19-G19,0) -> 0 | E19: =IF(E$9="n",F19-G19,0) -> 0 | G19: =IF(($E$11="n"),0,IF((LEFT(C19,1)="v"),F19,IF((LEFT(C19,1)="z"),0,F19*1/6))) -> 0 | J19: R S C S LTD | L19: 19800
D20: =IF(E$9="y",F20-G20,0) -> 0 | E20: =IF(E$9="n",F20-G20,0) -> 0 | G20: =IF(($E$11="n"),0,IF((LEFT(C20,1)="v"),F20,IF((LEFT(C20,1)="z"),0,F20*1/6))) -> 0 | P20: 1.52
D21: =IF(E$9="y",F21-G21,0) -> 0 | E21: =IF(E$9="n",F21-G21,0) -> 0 | G21: =IF(($E$11="n"),0,IF((LEFT(C21,1)="v"),F21,IF((LEFT(C21,1)="z"),0,F21*1/6))) -> 0
D22: =IF(E$9="y",F22-G22,0) -> 0 | E22: =IF(E$9="n",F22-G22,0) -> 0 | G22: =IF(($E$11="n"),0,IF((LEFT(C22,1)="v"),F22,IF((LEFT(C22,1)="z"),0,F22*1/6))) -> 0
D23: =IF(E$9="y",F23-G23,0) -> 0 | E23: =IF(E$9="n",F23-G23,0) -> 0 | G23: =IF(($E$11="n"),0,IF((LEFT(C23,1)="v"),F23,IF((LEFT(C23,1)="z"),0,F23*1/6))) -> 0
D24: =IF(E$9="y",F24-G24,0) -> 0 | E24: =IF(E$9="n",F24-G24,0) -> 0 | G24: =IF(($E$11="n"),0,IF((LEFT(C24,1)="v"),F24,IF((LEFT(C24,1)="z"),0,F24*1/6))) -> 0
D25: =IF(E$9="y",F25-G25,0) -> 0 | E25: =IF(E$9="n",F25-G25,0) -> 0 | G25: =IF(($E$11="n"),0,IF((LEFT(C25,1)="v"),F25,IF((LEFT(C25,1)="z"),0,F25*1/6))) -> 0
D26: =IF(E$9="y",F26-G26,0) -> 0 | E26: =IF(E$9="n",F26-G26,0) -> 0 | G26: =IF(($E$11="n"),0,IF((LEFT(C26,1)="v"),F26,IF((LEFT(C26,1)="z"),0,F26*1/6))) -> 0
D27: =IF(E$9="y",F27-G27,0) -> 0 | E27: =IF(E$9="n",F27-G27,0) -> 0 | G27: =IF(($E$11="n"),0,IF((LEFT(C27,1)="v"),F27,IF((LEFT(C27,1)="z"),0,F27*1/6))) -> 0
D28: =IF(E$9="y",F28-G28,0) -> 0 | E28: =IF(E$9="n",F28-G28,0) -> 0 | G28: =IF(($E$11="n"),0,IF((LEFT(C28,1)="v"),F28,IF((LEFT(C28,1)="z"),0,F28*1/6))) -> 0
D29: =IF(E$9="y",F29-G29,0) -> 0 | E29: =IF(E$9="n",F29-G29,0) -> 0 | G29: =IF(($E$11="n"),0,IF((LEFT(C29,1)="v"),F29,IF((LEFT(C29,1)="z"),0,F29*1/6))) -> 0
D30: =IF(E$9="y",F30-G30,0) -> 0 | E30: =IF(E$9="n",F30-G30,0) -> 0 | G30: =IF(($E$11="n"),0,IF((LEFT(C30,1)="v"),F30,IF((LEFT(C30,1)="z"),0,F30*1/6))) -> 0
D31: =IF(E$9="y",F31-G31,0) -> 0 | E31: =IF(E$9="n",F31-G31,0) -> 0 | G31: =IF(($E$11="n"),0,IF((LEFT(C31,1)="v"),F31,IF((LEFT(C31,1)="z"),0,F31*1/6))) -> 0
D32: =IF(E$9="y",F32-G32,0) -> 0 | E32: =IF(E$9="n",F32-G32,0) -> 0 | G32: =IF(($E$11="n"),0,IF((LEFT(C32,1)="v"),F32,IF((LEFT(C32,1)="z"),0,F32*1/6))) -> 0
... D40: =IF(E$9="y",F40-G40,0) -> 0 | E40: =IF(E$9="n",F40-G40,0) -> 0 | G40: =IF(($E$11="n"),0,IF((LEFT(C40,1)="v"),F40,IF((LEFT(C40,1)="z"),0,F40*1/6))) -> 0
B41: =IF(E9="Both","Enter manual values here",0) -> 0 | D41: =IF(E$9="y",F41-G41,0) -> 0 | E41: =IF(E$9="n",F41-G41,0) -> 0 | G41: =IF(($E$11="n"),0,IF((LEFT(C41,1)="v"),F41,IF((LEFT(C41,1)="z"),0,F41*1/6))) -> 0
D42: =IF(E$9="y",F42-G42,0) -> 0 | E42: =IF(E$9="n",F42-G42,0) -> 0 | G42: =IF(($E$11="n"),0,IF((LEFT(C42,1)="v"),F42,IF((LEFT(C42,1)="z"),0,F42*1/6))) -> 0
D43: =IF(E$9="y",F43-G43,0) -> 0 | E43: =IF(E$9="n",F43-G43,0) -> 0 | G43: =IF(($E$11="n"),0,IF((LEFT(C43,1)="v"),F43,IF((LEFT(C43,1)="z"),0,F43*1/6))) -> 0
D44: =IF(E$9="y",F44-G44,0) -> 0 | E44: =IF(E$9="n",F44-G44,0) -> 0 | G44: =IF(($E$11="n"),0,IF((LEFT(C44,1)="v"),F44,IF((LEFT(C44,1)="z"),0,F44*1/6))) -> 0
D45: =IF(E$9="y",F45-G45,0) -> 0 | E45: =IF(E$9="n",F45-G45,0) -> 0 | G45: =IF(($E$11="n"),0,IF((LEFT(C45,1)="v"),F45,IF((LEFT(C45,1)="z"),0,F45*1/6))) -> 0
D46: =IF(E$9="y",F46-G46,0) -> 0 | E46: =IF(E$9="n",F46-G46,0) -> 0 | G46: =IF(($E$11="n"),0,IF((LEFT(C46,1)="v"),F46,IF((LEFT(C46,1)="z"),0,F46*1/6))) -> 0
D47: =IF(E$9="y",F47-G47,0) -> 0 | E47: =IF(E$9="n",F47-G47,0) -> 0 | G47: =IF(($E$11="n"),0,IF((LEFT(C47,1)="v"),F47,IF((LEFT(C47,1)="z"),0,F47*1/6))) -> 0
D48: =IF(E$9="y",F48-G48,0) -> 0 | E48: =IF(E$9="n",F48-G48,0) -> 0 | G48: =IF(($E$11="n"),0,IF((LEFT(C48,1)="v"),F48,IF((LEFT(C48,1)="z"),0,F48*1/6))) -> 0
D49: =IF(E$9="y",F49-G49,0) -> 0 | E49: =IF(E$9="n",F49-G49,0) -> 0 | G49: =IF(($E$11="n"),0,IF((LEFT(C49,1)="v"),F49,IF((LEFT(C49,1)="z"),0,F49*1/6))) -> 0
D50: =IF(E$9="y",F50-G50,0) -> 0 | E50: =IF(E$9="n",F50-G50,0) -> 0 | G50: =IF(($E$11="n"),0,IF((LEFT(C50,1)="v"),F50,IF((LEFT(C50,1)="z"),0,F50*1/6))) -> 0
D51: =IF(E$9="y",F51-G51,0) -> 0 | E51: =IF(E$9="n",F51-G51,0) -> 0 | G51: =IF(($E$11="n"),0,IF((LEFT(C51,1)="v"),F51,IF((LEFT(C51,1)="z"),0,F51*1/6))) -> 0
D52: =IF(E$9="y",F52-G52,0) -> 0 | E52: =IF(E$9="n",F52-G52,0) -> 0 | G52: =IF(($E$11="n"),0,IF((LEFT(C52,1)="v"),F52,IF((LEFT(C52,1)="z"),0,F52*1/6))) -> 0
...

Sheet Jan 18
A1: 0
A2: ='Nov 17'!A2 -> Design-spectrum Limited
A4: Month | C4: ='Dec 17'!C4+31 -> 43102
A7: Sales Invoices | I7: Bankings - Receipts
A9: Does this months income fall within IR35? (Y/N/both) | E9: ='Dec 17'!E9 -> n
A11: Is the Company VAT registered (Y/N) | E11: ='Dec 17'!E11 -> y
A12: VAT Flat rate scheme percentage | E12: ='Dec 17'!E12 -> 0.165
A13: (leave blank or zero if not using flat rate scheme) | M13: Interest | O13: Transfers from | P13: Interest
L14: Sales Invoice | M14: Received on | O14: Deposit | P14: Received on
A15: Date | B15: Details | C15: Sales Invoice No | D15: IR35 | E15: Non IR35 | F15: Gross | G15: VAT | I15: Date | J15: Details | K15: Sales Invoice no | L15: Amount £ | M15: Current Account | N15: Other bankings | O15: Account | P15: Deposit Account
C16: Balance b/f | D16: ='Dec 17'!D54 -> 0 | E16: ='Dec 17'!E54 -> 19250 | F16: ='Dec 17'!F54 -> 23100 | G16: ='Dec 17'!G54 -> 3850 | J16: Balance b/f | L16: ='Dec 17'!L54 -> 42900 | M16: ='Dec 17'!M54 -> 66.53 | N16: ='Dec 17'!N54 -> 0 | O16: ='Dec 17'!O54 -> 50488.86 | P16: ='Dec 17'!P54 -> -63.58
B17: Raised in next month | D17: =IF(E$9="y",F17-G17,0) -> 0 | E17: =IF(E$9="n",F17-G17,0) -> 0 | G17: =IF(($E$11="n"),0,IF((LEFT(C17,1)="v"),F17,IF((LEFT(C17,1)="z"),0,F17*1/6))) -> 0 | J17: R S C S LTD | L17: 3300
D18: =IF(E$9="y",F18-G18,0) -> 0 | E18: =IF(E$9="n",F18-G18,0) -> 0 | G18: =IF(($E$11="n"),0,IF((LEFT(C18,1)="v"),F18,IF((LEFT(C18,1)="z"),0,F18*1/6))) -> 0 | P18: 2.5
D19: =IF(E$9="y",F19-G19,0) -> 0 | E19: =IF(E$9="n",F19-G19,0) -> 0 | G19: =IF(($E$11="n"),0,IF((LEFT(C19,1)="v"),F19,IF((LEFT(C19,1)="z"),0,F19*1/6))) -> 0
D20: =IF(E$9="y",F20-G20,0) -> 0 | E20: =IF(E$9="n",F20-G20,0) -> 0 | G20: =IF(($E$11="n"),0,IF((LEFT(C20,1)="v"),F20,IF((LEFT(C20,1)="z"),0,F20*1/6))) -> 0
D21: =IF(E$9="y",F21-G21,0) -> 0 | E21: =IF(E$9="n",F21-G21,0) -> 0 | G21: =IF(($E$11="n"),0,IF((LEFT(C21,1)="v"),F21,IF((LEFT(C21,1)="z"),0,F21*1/6))) -> 0
D22: =IF(E$9="y",F22-G22,0) -> 0 | E22: =IF(E$9="n",F22-G22,0) -> 0 | G22: =IF(($E$11="n"),0,IF((LEFT(C22,1)="v"),F22,IF((LEFT(C22,1)="z"),0,F22*1/6))) -> 0
D23: =IF(E$9="y",F23-G23,0) -> 0 | E23: =IF(E$9="n",F23-G23,0) -> 0 | G23: =IF(($E$11="n"),0,IF((LEFT(C23,1)="v"),F23,IF((LEFT(C23,1)="z"),0,F23*1/6))) -> 0
D24: =IF(E$9="y",F24-G24,0) -> 0 | E24: =IF(E$9="n",F24-G24,0) -> 0 | G24: =IF(($E$11="n"),0,IF((LEFT(C24,1)="v"),F24,IF((LEFT(C24,1)="z"),0,F24*1/6))) -> 0
D25: =IF(E$9="y",F25-G25,0) -> 0 | E25: =IF(E$9="n",F25-G25,0) -> 0 | G25: =IF(($E$11="n"),0,IF((LEFT(C25,1)="v"),F25,IF((LEFT(C25,1)="z"),0,F25*1/6))) -> 0
D26: =IF(E$9="y",F26-G26,0) -> 0 | E26: =IF(E$9="n",F26-G26,0) -> 0 | G26: =IF(($E$11="n"),0,IF((LEFT(C26,1)="v"),F26,IF((LEFT(C26,1)="z"),0,F26*1/6))) -> 0
D27: =IF(E$9="y",F27-G27,0) -> 0 | E27: =IF(E$9="n",F27-G27,0) -> 0 | G27: =IF(($E$11="n"),0,IF((LEFT(C27,1)="v"),F27,IF((LEFT(C27,1)="z"),0,F27*1/6))) -> 0
D28: =IF(E$9="y",F28-G28,0) -> 0 | E28: =IF(E$9="n",F28-G28,0) -> 0 | G28: =IF(($E$11="n"),0,IF((LEFT(C28,1)="v"),F28,IF((LEFT(C28,1)="z"),0,F28*1/6))) -> 0
D29: =IF(E$9="y",F29-G29,0) -> 0 | E29: =IF(E$9="n",F29-G29,0) -> 0 | G29: =IF(($E$11="n"),0,IF((LEFT(C29,1)="v"),F29,IF((LEFT(C29,1)="z"),0,F29*1/6))) -> 0
D30: =IF(E$9="y",F30-G30,0) -> 0 | E30: =IF(E$9="n",F30-G30,0) -> 0 | G30: =IF(($E$11="n"),0,IF((LEFT(C30,1)="v"),F30,IF((LEFT(C30,1)="z"),0,F30*1/6))) -> 0
... D40: =IF(E$9="y",F40-G40,0) -> 0 | E40: =IF(E$9="n",F40-G40,0) -> 0 | G40: =IF(($E$11="n"),0,IF((LEFT(C40,1)="v"),F40,IF((LEFT(C40,1)="z"),0,F40*1/6))) -> 0
B41: =IF(E9="Both","Enter manual values here",0) -> 0 | D41: =IF(E$9="y",F41-G41,0) -> 0 | E41: =IF(E$9="n",F41-G41,0) -> 0 | G41: =IF(($E$11="n"),0,IF((LEFT(C41,1)="v"),F41,IF((LEFT(C41,1)="z"),0,F41*1/6))) -> 0
D42: =IF(E$9="y",F42-G42,0) -> 0 | E42: =IF(E$9="n",F42-G42,0) -> 0 | G42: =IF(($E$11="n"),0,IF((LEFT(C42,1)="v"),F42,IF((LEFT(C42,1)="z"),0,F42*1/6))) -> 0
D43: =IF(E$9="y",F43-G43,0) -> 0 | E43: =IF(E$9="n",F43-G43,0) -> 0 | G43: =IF(($E$11="n"),0,IF((LEFT(C43,1)="v"),F43,IF((LEFT(C43,1)="z"),0,F43*1/6))) -> 0
D44: =IF(E$9="y",F44-G44,0) -> 0 | E44: =IF(E$9="n",F44-G44,0) -> 0 | G44: =IF(($E$11="n"),0,IF((LEFT(C44,1)="v"),F44,IF((LEFT(C44,1)="z"),0,F44*1/6))) -> 0
D45: =IF(E$9="y",F45-G45,0) -> 0 | E45: =IF(E$9="n",F45-G45,0) -> 0 | G45: =IF(($E$11="n"),0,IF((LEFT(C45,1)="v"),F45,IF((LEFT(C45,1)="z"),0,F45*1/6))) -> 0
D46: =IF(E$9="y",F46-G46,0) -> 0 | E46: =IF(E$9="n",F46-G46,0) -> 0 | G46: =IF(($E$11="n"),0,IF((LEFT(C46,1)="v"),F46,IF((LEFT(C46,1)="z"),0,F46*1/6))) -> 0
D47: =IF(E$9="y",F47-G47,0) -> 0 | E47: =IF(E$9="n",F47-G47,0) -> 0 | G47: =IF(($E$11="n"),0,IF((LEFT(C47,1)="v"),F47,IF((LEFT(C47,1)="z"),0,F47*1/6))) -> 0
D48: =IF(E$9="y",F48-G48,0) -> 0 | E48: =IF(E$9="n",F48-G48,0) -> 0 | G48: =IF(($E$11="n"),0,IF((LEFT(C48,1)="v"),F48,IF((LEFT(C48,1)="z"),0,F48*1/6))) -> 0
D49: =IF(E$9="y",F49-G49,0) -> 0 | E49: =IF(E$9="n",F49-G49,0) -> 0 | G49: =IF(($E$11="n"),0,IF((LEFT(C49,1)="v"),F49,IF((LEFT(C49,1)="z"),0,F49*1/6))) -> 0
D50: =IF(E$9="y",F50-G50,0) -> 0 | E50: =IF(E$9="n",F50-G50,0) -> 0 | G50: =IF(($E$11="n"),0,IF((LEFT(C50,1)="v"),F50,IF((LEFT(C50,1)="z"),0,F50*1/6))) -> 0
D51: =IF(E$9="y",F51-G51,0) -> 0 | E51: =IF(E$9="n",F51-G51,0) -> 0 | G51: =IF(($E$11="n"),0,IF((LEFT(C51,1)="v"),F51,IF((LEFT(C51,1)="z"),0,F51*1/6))) -> 0
D52: =IF(E$9="y",F52-G52,0) -> 0 | E52: =IF(E$9="n",F52-G52,0) -> 0 | G52: =IF(($E$11="n"),0,IF((LEFT(C52,1)="v"),F52,IF((LEFT(C52,1)="z"),0,F52*1/6))) -> 0
A53: Total | D53: =SUM(D17:D52) -> 0 | E53: =SUM(E17:E52) -> 0 | F53: =SUM(F17:F52) -> 0 | G53: =SUM(G17:G52) -> 0 | I53: Total | L53: =SUM(L17:L52) -> 3300 | M53: =SUM(M17:M52) -> 0 | N53: =SUM(N17:N52) -> 0 | O53: =SUM(O17:O52) -> 0 | P53: =SUM(P17:P52) -> 2.5
A54: C/fwd | D54: =SUM(D16:D52) -> 0 | E54: =SUM(E16:E52) -> 19250 | F54: =SUM(F16:F52) -> 23100 | G54: =SUM(G16:G52) -> 3850 | I54: C/fwd | L54: =SUM(L16:L52) -> 46200 | M54: =SUM(M16:M52) -> 66.53 | N54: =SUM(N16:N52) -> 0 | O54: =SUM(O16:O52) -> 50488.86 | P54: =SUM(P16:P52) -> -61.08
...

Sheet Feb 18
A2: ='Nov 17'!A2 -> Design-spectrum Limited
A4: Month | C4: ='Jan 18'!C4+31 -> 43133
A7: Sales Invoices | I7: Bankings - Receipts
A9: Does this months income fall within IR35? (Y/N/both) | E9: ='Jan 18'!E9 -> n | F9: =IF(E9="Both","enter sales invoices manually at row 30 onwards",0) -> 0
A11: Is the Company VAT registered (Y/N) | E11: ='Jan 18'!E11 -> y
A12: VAT Flat rate scheme percentage | E12: ='Jan 18'!E12 -> 0.165
A13: (leave blank or zero if not using flat rate scheme) | M13: Interest | O13: Transfers from | P13: Interest
L14: Sales Invoice | M14: Received on | O14: Deposit | P14: Received on
A15: Date | B15: Details | C15: Sales Invoice No | D15: IR35 | E15: Non IR35 | F15: Gross | G15: VAT | I15: Date | J15: Details | K15: Sales Invoice no | L15: Amount £ | M15: Current Account | N15: Other bankings | O15: Account | P15: Deposit Account
C16: Balance b/f | D16: ='Jan 18'!D54 -> 0 | E16: ='Jan 18'!E54 -> 19250 | F16: ='Jan 18'!F54 -> 23100 | G16: ='Jan 18'!G54 -> 3850 | J16: Balance b/f | L16: ='Jan 18'!L54 -> 46200 | M16: ='Jan 18'!M54 -> 66.53 | N16: ='Jan 18'!N54 -> 0 | O16: ='Jan 18'!O54 -> 50488.86 | P16: ='Jan 18'!P54 -> -61.08
B17: Invoice 2Jan-2Feb2018 | D17: =IF(E$9="y",F17-G17,0) -> 0 | E17: =IF(E$9="n",F17-G17,0) -> 13200 | F17: 15840 | G17: =IF(($E$11="n"),0,IF((LEFT(C17,1)="v"),F17,IF((LEFT(C17,1)="z"),0,F17*1/6))) -> 2640 | J17: R S C S LTD | L17: 15840
D18: =IF(E$9="y",F18-G18,0) -> 0 | E18: =IF(E$9="n",F18-G18,0) -> 0 | G18: =IF(($E$11="n"),0,IF((LEFT(C18,1)="v"),F18,IF((LEFT(C18,1)="z"),0,F18*1/6))) -> 0 | P18: 2.5
D19: =IF(E$9="y",F19-G19,0) -> 0 | E19: =IF(E$9="n",F19-G19,0) -> 0 | G19: =IF(($E$11="n"),0,IF((LEFT(C19,1)="v"),F19,IF((LEFT(C19,1)="z"),0,F19*1/6))) -> 0
D20: =IF(E$9="y",F20-G20,0) -> 0 | E20: =IF(E$9="n",F20-G20,0) -> 0 | G20: =IF(($E$11="n"),0,IF((LEFT(C20,1)="v"),F20,IF((LEFT(C20,1)="z"),0,F20*1/6))) -> 0
D21: =IF(E$9="y",F21-G21,0) -> 0 | E21: =IF(E$9="n",F21-G21,0) -> 0 | G21: =IF(($E$11="n"),0,IF((LEFT(C21,1)="v"),F21,IF((LEFT(C21,1)="z"),0,F21*1/6))) -> 0
D22: =IF(E$9="y",F22-G22,0) -> 0 | E22: =IF(E$9="n",F22-G22,0) -> 0 | G22: =IF(($E$11="n"),0,IF((LEFT(C22,1)="v"),F22,IF((LEFT(C22,1)="z"),0,F22*1/6))) -> 0
D23: =IF(E$9="y",F23-G23,0) -> 0 | E23: =IF(E$9="n",F23-G23,0) -> 0 | G23: =IF(($E$11="n"),0,IF((LEFT(C23,1)="v"),F23,IF((LEFT(C23,1)="z"),0,F23*1/6))) -> 0
D24: =IF(E$9="y",F24-G24,0) -> 0 | E24: =IF(E$9="n",F24-G24,0) -> 0 | G24: =IF(($E$11="n"),0,IF((LEFT(C24,1)="v"),F24,IF((LEFT(C24,1)="z"),0,F24*1/6))) -> 0
D25: =IF(E$9="y",F25-G25,0) -> 0 | E25: =IF(E$9="n",F25-G25,0) -> 0 | G25: =IF(($E$11="n"),0,IF((LEFT(C25,1)="v"),F25,IF((LEFT(C25,1)="z"),0,F25*1/6))) -> 0
D26: =IF(E$9="y",F26-G26,0) -> 0 | E26: =IF(E$9="n",F26-G26,0) -> 0 | G26: =IF(($E$11="n"),0,IF((LEFT(C26,1)="v"),F26,IF((LEFT(C26,1)="z"),0,F26*1/6))) -> 0
D27: =IF(E$9="y",F27-G27,0) -> 0 | E27: =IF(E$9="n",F27-G27,0) -> 0 | G27: =IF(($E$11="n"),0,IF((LEFT(C27,1)="v"),F27,IF((LEFT(C27,1)="z"),0,F27*1/6))) -> 0
D28: =IF(E$9="y",F28-G28,0) -> 0 | E28: =IF(E$9="n",F28-G28,0) -> 0 | G28: =IF(($E$11="n"),0,IF((LEFT(C28,1)="v"),F28,IF((LEFT(C28,1)="z"),0,F28*1/6))) -> 0
D29: =IF(E$9="y",F29-G29,0) -> 0 | E29: =IF(E$9="n",F29-G29,0) -> 0 | G29: =IF(($E$11="n"),0,IF((LEFT(C29,1)="v"),F29,IF((LEFT(C29,1)="z"),0,F29*1/6))) -> 0
D30: =IF(E$9="y",F30-G30,0) -> 0 | E30: =IF(E$9="n",F30-G30,0) -> 0 | G30: =IF(($E$11="n"),0,IF((LEFT(C30,1)="v"),F30,IF((LEFT(C30,1)="z"),0,F30*1/6))) -> 0
... D40: =IF(E$9="y",F40-G40,0) -> 0 | E40: =IF(E$9="n",F40-G40,0) -> 0 | G40: =IF(($E$11="n"),0,IF((LEFT(C40,1)="v"),F40,IF((LEFT(C40,1)="z"),0,F40*1/6))) -> 0
B41: =IF(E9="Both","Enter manual values here",0) -> 0 | D41: =IF(E$9="y",F41-G41,0) -> 0 | E41: =IF(E$9="n",F41-G41,0) -> 0 | G41: =IF(($E$11="n"),0,IF((LEFT(C41,1)="v"),F41,IF((LEFT(C41,1)="z"),0,F41*1/6))) -> 0
D42: =IF(E$9="y",F42-G42,0) -> 0 | E42: =IF(E$9="n",F42-G42,0) -> 0 | G42: =IF(($E$11="n"),0,IF((LEFT(C42,1)="v"),F42,IF((LEFT(C42,1)="z"),0,F42*1/6))) -> 0
D43: =IF(E$9="y",F43-G43,0) -> 0 | E43: =IF(E$9="n",F43-G43,0) -> 0 | G43: =IF(($E$11="n"),0,IF((LEFT(C43,1)="v"),F43,IF((LEFT(C43,1)="z"),0,F43*1/6))) -> 0
D44: =IF(E$9="y",F44-G44,0) -> 0 | E44: =IF(E$9="n",F44-G44,0) -> 0 | G44: =IF(($E$11="n"),0,IF((LEFT(C44,1)="v"),F44,IF((LEFT(C44,1)="z"),0,F44*1/6))) -> 0
D45: =IF(E$9="y",F45-G45,0) -> 0 | E45: =IF(E$9="n",F45-G45,0) -> 0 | G45: =IF(($E$11="n"),0,IF((LEFT(C45,1)="v"),F45,IF((LEFT(C45,1)="z"),0,F45*1/6))) -> 0
D46: =IF(E$9="y",F46-G46,0) -> 0 | E46: =IF(E$9="n",F46-G46,0) -> 0 | G46: =IF(($E$11="n"),0,IF((LEFT(C46,1)="v"),F46,IF((LEFT(C46,1)="z"),0,F46*1/6))) -> 0
D47: =IF(E$9="y",F47-G47,0) -> 0 | E47: =IF(E$9="n",F47-G47,0) -> 0 | G47: =IF(($E$11="n"),0,IF((LEFT(C47,1)="v"),F47,IF((LEFT(C47,1)="z"),0,F47*1/6))) -> 0
D48: =IF(E$9="y",F48-G48,0) -> 0 | E48: =IF(E$9="n",F48-G48,0) -> 0 | G48: =IF(($E$11="n"),0,IF((LEFT(C48,1)="v"),F48,IF((LEFT(C48,1)="z"),0,F48*1/6))) -> 0
D49: =IF(E$9="y",F49-G49,0) -> 0 | E49: =IF(E$9="n",F49-G49,0) -> 0 | G49: =IF(($E$11="n"),0,IF((LEFT(C49,1)="v"),F49,IF((LEFT(C49,1)="z"),0,F49*1/6))) -> 0
D50: =IF(E$9="y",F50-G50,0) -> 0 | E50: =IF(E$9="n",F50-G50,0) -> 0 | G50: =IF(($E$11="n"),0,IF((LEFT(C50,1)="v"),F50,IF((LEFT(C50,1)="z"),0,F50*1/6))) -> 0
D51: =IF(E$9="y",F51-G51,0) -> 0 | E51: =IF(E$9="n",F51-G51,0) -> 0 | G51: =IF(($E$11="n"),0,IF((LEFT(C51,1)="v"),F51,IF((LEFT(C51,1)="z"),0,F51*1/6))) -> 0
D52: =IF(E$9="y",F52-G52,0) -> 0 | E52: =IF(E$9="n",F52-G52,0) -> 0 | G52: =IF(($E$11="n"),0,IF((LEFT(C52,1)="v"),F52,IF((LEFT(C52,1)="z"),0,F52*1/6))) -> 0
A53: Total | D53: =SUM(D17:D52) -> 0 | E53: =SUM(E17:E52) -> 13200 | F53: =SUM(F17:F52) -> 15840 | G53: =SUM(G17:G52) -> 2640 | I53: Total | L53: =SUM(L17:L52) -> 15840 | M53: =SUM(M17:M52) -> 0 | N53: =SUM(N17:N52) -> 0 | O53: =SUM(O17:O52) -> 0 | P53: =SUM(P17:P52) -> 2.5
A54: C/fwd | D54: =SUM(D16:D52) -> 0 | E54: =SUM(E16:E52) -> 32450 | F54: =SUM(F16:F52) -> 38940 | G54: =SUM(G16:G52) -> 6490 | I54: C/fwd | L54: =SUM(L16:L52) -> 62040 | M54: =SUM(M16:M52) -> 66.53 | N54: =SUM(N16:N52) -> 0 | O54: =SUM(O16:O52) -> 50488.86 | P54: =SUM(P16:P52) -> -58.58
A56: IR35 Details (ignore if outside IR35): | D56: Flat Rate Scheme Details (ignore if outside FRS):
...

Sheet Mar 18
A1: 0
A2: ='Nov 17'!A2 -> Design-spectrum Limited
A4: Month | C4: ='Feb 18'!C4+31 -> 43164
A7: Sales Invoices | I7: Bankings - Receipts
A9: Does this months income fall within IR35? (Y/N/both) | E9: ='Feb 18'!E9 -> n | F9: =IF(E9="Both","enter sales invoices manually at row 30 onwards",0) -> 0
A11: Is the Company VAT registered (Y/N) | E11: ='Feb 18'!E11 -> y
A12: VAT Flat rate scheme percentage | E12: ='Feb 18'!E12 -> 0.165
A13: (leave blank or zero if not using flat rate scheme) | M13: Interest | O13: Transfers from | P13: Interest
L14: Sales Invoice | M14: Received on | O14: Deposit | P14: Received on
A15: Date | B15: Details | C15: Sales Invoice No | D15: IR35 | E15: Non IR35 | F15: Gross | G15: VAT | I15: Date | J15: Details | K15: Sales Invoice no | L15: Amount £ | M15: Current Account | N15: Other bankings | O15: Account | P15: Deposit Account
C16: Balance b/f | D16: ='Feb 18'!D54 -> 0 | E16: ='Feb 18'!E54 -> 32450 | F16: ='Feb 18'!F54 -> 38940 | G16: ='Feb 18'!G54 -> 6490 | J16: Balance b/f | L16: ='Feb 18'!L54 -> 62040 | M16: ='Feb 18'!M54 -> 66.53 | N16: ='Feb 18'!N54 -> 0 | O16: ='Feb 18'!O54 -> 50488.86 | P16: ='Feb 18'!P54 -> -58.58
B17: Invoice 2Feb-2Mar2018 | D17: =IF(E$9="y",F17-G17,0) -> 0 | E17: =IF(E$9="n",F17-G17,0) -> 11000 | F17: 13200 | G17: =IF(($E$11="n"),0,IF((LEFT(C17,1)="v"),F17,IF((LEFT(C17,1)="z"),0,F17*1/6))) -> 2200 | I17: 43182 | J17: R S C S LTD | L17: 13200
D18: =IF(E$9="y",F18-G18,0) -> 0 | E18: =IF(E$9="n",F18-G18,0) -> 0 | G18: =IF(($E$11="n"),0,IF((LEFT(C18,1)="v"),F18,IF((LEFT(C18,1)="z"),0,F18*1/6))) -> 0 | P18: 2.26
D19: =IF(E$9="y",F19-G19,0) -> 0 | E19: =IF(E$9="n",F19-G19,0) -> 0 | G19: =IF(($E$11="n"),0,IF((LEFT(C19,1)="v"),F19,IF((LEFT(C19,1)="z"),0,F19*1/6))) -> 0
D20: =IF(E$9="y",F20-G20,0) -> 0 | E20: =IF(E$9="n",F20-G20,0) -> 0 | G20: =IF(($E$11="n"),0,IF((LEFT(C20,1)="v"),F20,IF((LEFT(C20,1)="z"),0,F20*1/6))) -> 0
D21: =IF(E$9="y",F21-G21,0) -> 0 | E21: =IF(E$9="n",F21-G21,0) -> 0 | G21: =IF(($E$11="n"),0,IF((LEFT(C21,1)="v"),F21,IF((LEFT(C21,1)="z"),0,F21*1/6))) -> 0
D22: =IF(E$9="y",F22-G22,0) -> 0 | E22: =IF(E$9="n",F22-G22,0) -> 0 | G22: =IF(($E$11="n"),0,IF((LEFT(C22,1)="v"),F22,IF((LEFT(C22,1)="z"),0,F22*1/6))) -> 0
D23: =IF(E$9="y",F23-G23,0) -> 0 | E23: =IF(E$9="n",F23-G23,0) -> 0 | G23: =IF(($E$11="n"),0,IF((LEFT(C23,1)="v"),F23,IF((LEFT(C23,1)="z"),0,F23*1/6))) -> 0
D24: =IF(E$9="y",F24-G24,0) -> 0 | E24: =IF(E$9="n",F24-G24,0) -> 0 | G24: =IF(($E$11="n"),0,IF((LEFT(C24,1)="v"),F24,IF((LEFT(C24,1)="z"),0,F24*1/6))) -> 0
D25: =IF(E$9="y",F25-G25,0) -> 0 | E25: =IF(E$9="n",F25-G25,0) -> 0 | G25: =IF(($E$11="n"),0,IF((LEFT(C25,1)="v"),F25,IF((LEFT(C25,1)="z"),0,F25*1/6))) -> 0
D26: =IF(E$9="y",F26-G26,0) -> 0 | E26: =IF(E$9="n",F26-G26,0) -> 0 | G26: =IF(($E$11="n"),0,IF((LEFT(C26,1)="v"),F26,IF((LEFT(C26,1)="z"),0,F26*1/6))) -> 0
D27: =IF(E$9="y",F27-G27,0) -> 0 | E27: =IF(E$9="n",F27-G27,0) -> 0 | G27: =IF(($E$11="n"),0,IF((LEFT(C27,1)="v"),F27,IF((LEFT(C27,1)="z"),0,F27*1/6))) -> 0
D28: =IF(E$9="y",F28-G28,0) -> 0 | E28: =IF(E$9="n",F28-G28,0) -> 0 | G28: =IF(($E$11="n"),0,IF((LEFT(C28,1)="v"),F28,IF((LEFT(C28,1)="z"),0,F28*1/6))) -> 0
D29: =IF(E$9="y",F29-G29,0) -> 0 | E29: =IF(E$9="n",F29-G29,0) -> 0 | G29: =IF(($E$11="n"),0,IF((LEFT(C29,1)="v"),F29,IF((LEFT(C29,1)="z"),0,F29*1/6))) -> 0
D30: =IF(E$9="y",F30-G30,0) -> 0 | E30: =IF(E$9="n",F30-G30,0) -> 0 | G30: =IF(($E$11="n"),0,IF((LEFT(C30,1)="v"),F30,IF((LEFT(C30,1)="z"),0,F30*1/6))) -> 0
... D40: =IF(E$9="y",F40-G40,0) -> 0 | E40: =IF(E$9="n",F40-G40,0) -> 0 | G40: =IF(($E$11="n"),0,IF((LEFT(C40,1)="v"),F40,IF((LEFT(C40,1)="z"),0,F40*1/6))) -> 0
B41: =IF(E9="Both","Enter manual values here",0) -> 0 | D41: =IF(E$9="y",F41-G41,0) -> 0 | E41: =IF(E$9="n",F41-G41,0) -> 0 | G41: =IF(($E$11="n"),0,IF((LEFT(C41,1)="v"),F41,IF((LEFT(C41,1)="z"),0,F41*1/6))) -> 0
D42: =IF(E$9="y",F42-G42,0) -> 0 | E42: =IF(E$9="n",F42-G42,0) -> 0 | G42: =IF(($E$11="n"),0,IF((LEFT(C42,1)="v"),F42,IF((LEFT(C42,1)="z"),0,F42*1/6))) -> 0
D43: =IF(E$9="y",F43-G43,0) -> 0 | E43: =IF(E$9="n",F43-G43,0) -> 0 | G43: =IF(($E$11="n"),0,IF((LEFT(C43,1)="v"),F43,IF((LEFT(C43,1)="z"),0,F43*1/6))) -> 0
D44: =IF(E$9="y",F44-G44,0) -> 0 | E44: =IF(E$9="n",F44-G44,0) -> 0 | G44: =IF(($E$11="n"),0,IF((LEFT(C44,1)="v"),F44,IF((LEFT(C44,1)="z"),0,F44*1/6))) -> 0
D45: =IF(E$9="y",F45-G45,0) -> 0 | E45: =IF(E$9="n",F45-G45,0) -> 0 | G45: =IF(($E$11="n"),0,IF((LEFT(C45,1)="v"),F45,IF((LEFT(C45,1)="z"),0,F45*1/6))) -> 0
D46: =IF(E$9="y",F46-G46,0) -> 0 | E46: =IF(E$9="n",F46-G46,0) -> 0 | G46: =IF(($E$11="n"),0,IF((LEFT(C46,1)="v"),F46,IF((LEFT(C46,1)="z"),0,F46*1/6))) -> 0
D47: =IF(E$9="y",F47-G47,0) -> 0 | E47: =IF(E$9="n",F47-G47,0) -> 0 | G47: =IF(($E$11="n"),0,IF((LEFT(C47,1)="v"),F47,IF((LEFT(C47,1)="z"),0,F47*1/6))) -> 0
D48: =IF(E$9="y",F48-G48,0) -> 0 | E48: =IF(E$9="n",F48-G48,0) -> 0 | G48: =IF(($E$11="n"),0,IF((LEFT(C48,1)="v"),F48,IF((LEFT(C48,1)="z"),0,F48*1/6))) -> 0
D49: =IF(E$9="y",F49-G49,0) -> 0 | E49: =IF(E$9="n",F49-G49,0) -> 0 | G49: =IF(($E$11="n"),0,IF((LEFT(C49,1)="v"),F49,IF((LEFT(C49,1)="z"),0,F49*1/6))) -> 0
D50: =IF(E$9="y",F50-G50,0) -> 0 | E50: =IF(E$9="n",F50-G50,0) -> 0 | G50: =IF(($E$11="n"),0,IF((LEFT(C50,1)="v"),F50,IF((LEFT(C50,1)="z"),0,F50*1/6))) -> 0
D51: =IF(E$9="y",F51-G51,0) -> 0 | E51: =IF(E$9="n",F51-G51,0) -> 0 | G51: =IF(($E$11="n"),0,IF((LEFT(C51,1)="v"),F51,IF((LEFT(C51,1)="z"),0,F51*1/6))) -> 0
D52: =IF(E$9="y",F52-G52,0) -> 0 | E52: =IF(E$9="n",F52-G52,0) -> 0 | G52: =IF(($E$11="n"),0,IF((LEFT(C52,1)="v"),F52,IF((LEFT(C52,1)="z"),0,F52*1/6))) -> 0
A53: Total | D53: =SUM(D17:D52) -> 0 | E53: =SUM(E17:E52) -> 11000 | F53: =SUM(F17:F52) -> 13200 | G53: =SUM(G17:G52) -> 2200 | I53: Total | L53: =SUM(L17:L52) -> 13200 | M53: =SUM(M17:M52) -> 0 | N53: =SUM(N17:N52) -> 0 | O53: =SUM(O17:O52) -> 0 | P53: =SUM(P17:P52) -> 2.26
A54: C/fwd | D54: =SUM(D16:D52) -> 0 | E54: =SUM(E16:E52) -> 43450 | F54: =SUM(F16:F52) -> 52140 | G54: =SUM(G16:G52) -> 8690 | I54: C/fwd | L54: =SUM(L16:L52) -> 75240 | M54: =SUM(M16:M52) -> 66.53 | N54: =SUM(N16:N52) -> 0 | O54: =SUM(O16:O52) -> 50488.86 | P54: =SUM(P16:P52) -> -56.32
...

Sheet Apr 18
A1: 0
A2: ='Nov 17'!A2 -> Design-spectrum Limited
A4: Month | C4: ='Mar 18'!C4+31 -> 43195
A7: Sales Invoices | I7: Bankings - Receipts
A9: Does this months income fall within IR35? (Y/N/both) | E9: ='Mar 18'!E9 -> n | F9: =IF(E9="Both","enter sales invoices manually at row 30 onwards",0) -> 0
A11: Is the Company VAT registered (Y/N) | E11: ='Mar 18'!E11 -> y
A12: VAT Flat rate scheme percentage | E12: ='Mar 18'!E12 -> 0.165
A13: (leave blank or zero if not using flat rate scheme) | M13: Interest | O13: Transfers from | P13: Interest
L14: Sales Invoice | M14: Received on | O14: Deposit | P14: Received on
A15: Date | B15: Details | C15: Sales Invoice No | D15: IR35 | E15: Non IR35 | F15: Gross | G15: VAT | I15: Date | J15: Details | K15: Sales Invoice no | L15: Amount £ | M15: Current Account | N15: Other bankings | O15: Account | P15: Deposit Account
C16: Balance b/f | D16: ='Mar 18'!D54 -> 0 | E16: ='Mar 18'!E54 -> 43450 | F16: ='Mar 18'!F54 -> 52140 | G16: ='Mar 18'!G54 -> 8690 | J16: Balance b/f | L16: ='Mar 18'!L54 -> 75240 | M16: ='Mar 18'!M54 -> 66.53 | N16: ='Mar 18'!N54 -> 0 | O16: ='Mar 18'!O54 -> 50488.86 | P16: ='Mar 18'!P54 -> -56.32
B17: Invoice 5Mar-15Apr2018 | D17: =IF(E$9="y",F17-G17,0) -> 0 | E17: =IF(E$9="n",F17-G17,0) -> 11550 | F17: 13860 | G17: =IF(($E$11="n"),0,IF((LEFT(C17,1)="v"),F17,IF((LEFT(C17,1)="z"),0,F17*1/6))) -> 2310 | I17: 43210 | J17: R S C S LTD | L17: 13860
D18: =IF(E$9="y",F18-G18,0) -> 0 | E18: =IF(E$9="n",F18-G18,0) -> 0 | G18: =IF(($E$11="n"),0,IF((LEFT(C18,1)="v"),F18,IF((LEFT(C18,1)="z"),0,F18*1/6))) -> 0 | P18: 2.5
D19: =IF(E$9="y",F19-G19,0) -> 0 | E19: =IF(E$9="n",F19-G19,0) -> 0 | G19: =IF(($E$11="n"),0,IF((LEFT(C19,1)="v"),F19,IF((LEFT(C19,1)="z"),0,F19*1/6))) -> 0
D20: =IF(E$9="y",F20-G20,0) -> 0 | E20: =IF(E$9="n",F20-G20,0) -> 0 | G20: =IF(($E$11="n"),0,IF((LEFT(C20,1)="v"),F20,IF((LEFT(C20,1)="z"),0,F20*1/6))) -> 0
D21: =IF(E$9="y",F21-G21,0) -> 0 | E21: =IF(E$9="n",F21-G21,0) -> 0 | G21: =IF(($E$11="n"),0,IF((LEFT(C21,1)="v"),F21,IF((LEFT(C21,1)="z"),0,F21*1/6))) -> 0
D22: =IF(E$9="y",F22-G22,0) -> 0 | E22: =IF(E$9="n",F22-G22,0) -> 0 | G22: =IF(($E$11="n"),0,IF((LEFT(C22,1)="v"),F22,IF((LEFT(C22,1)="z"),0,F22*1/6))) -> 0
D23: =IF(E$9="y",F23-G23,0) -> 0 | E23: =IF(E$9="n",F23-G23,0) -> 0 | G23: =IF(($E$11="n"),0,IF((LEFT(C23,1)="v"),F23,IF((LEFT(C23,1)="z"),0,F23*1/6))) -> 0
D24: =IF(E$9="y",F24-G24,0) -> 0 | E24: =IF(E$9="n",F24-G24,0) -> 0 | G24: =IF(($E$11="n"),0,IF((LEFT(C24,1)="v"),F24,IF((LEFT(C24,1)="z"),0,F24*1/6))) -> 0
D25: =IF(E$9="y",F25-G25,0) -> 0 | E25: =IF(E$9="n",F25-G25,0) -> 0 | G25: =IF(($E$11="n"),0,IF((LEFT(C25,1)="v"),F25,IF((LEFT(C25,1)="z"),0,F25*1/6))) -> 0
D26: =IF(E$9="y",F26-G26,0) -> 0 | E26: =IF(E$9="n",F26-G26,0) -> 0 | G26: =IF(($E$11="n"),0,IF((LEFT(C26,1)="v"),F26,IF((LEFT(C26,1)="z"),0,F26*1/6))) -> 0
D27: =IF(E$9="y",F27-G27,0) -> 0 | E27: =IF(E$9="n",F27-G27,0) -> 0 | G27: =IF(($E$11="n"),0,IF((LEFT(C27,1)="v"),F27,IF((LEFT(C27,1)="z"),0,F27*1/6))) -> 0
D28: =IF(E$9="y",F28-G28,0) -> 0 | E28: =IF(E$9="n",F28-G28,0) -> 0 | G28: =IF(($E$11="n"),0,IF((LEFT(C28,1)="v"),F28,IF((LEFT(C28,1)="z"),0,F28*1/6))) -> 0
D29: =IF(E$9="y",F29-G29,0) -> 0 | E29: =IF(E$9="n",F29-G29,0) -> 0 | G29: =IF(($E$11="n"),0,IF((LEFT(C29,1)="v"),F29,IF((LEFT(C29,1)="z"),0,F29*1/6))) -> 0
D30: =IF(E$9="y",F30-G30,0) -> 0 | E30: =IF(E$9="n",F30-G30,0) -> 0 | G30: =IF(($E$11="n"),0,IF((LEFT(C30,1)="v"),F30,IF((LEFT(C30,1)="z"),0,F30*1/6))) -> 0
... D40: =IF(E$9="y",F40-G40,0) -> 0 | E40: =IF(E$9="n",F40-G40,0) -> 0 | G40: =IF(($E$11="n"),0,IF((LEFT(C40,1)="v"),F40,IF((LEFT(C40,1)="z"),0,F40*1/6))) -> 0
B41: =IF(E9="Both","Enter manual values here",0) -> 0 | D41: =IF(E$9="y",F41-G41,0) -> 0 | E41: =IF(E$9="n",F41-G41,0) -> 0 | G41: =IF(($E$11="n"),0,IF((LEFT(C41,1)="v"),F41,IF((LEFT(C41,1)="z"),0,F41*1/6))) -> 0
D42: =IF(E$9="y",F42-G42,0) -> 0 | E42: =IF(E$9="n",F42-G42,0) -> 0 | G42: =IF(($E$11="n"),0,IF((LEFT(C42,1)="v"),F42,IF((LEFT(C42,1)="z"),0,F42*1/6))) -> 0
D43: =IF(E$9="y",F43-G43,0) -> 0 | E43: =IF(E$9="n",F43-G43,0) -> 0 | G43: =IF(($E$11="n"),0,IF((LEFT(C43,1)="v"),F43,IF((LEFT(C43,1)="z"),0,F43*1/6))) -> 0
D44: =IF(E$9="y",F44-G44,0) -> 0 | E44: =IF(E$9="n",F44-G44,0) -> 0 | G44: =IF(($E$11="n"),0,IF((LEFT(C44,1)="v"),F44,IF((LEFT(C44,1)="z"),0,F44*1/6))) -> 0
D45: =IF(E$9="y",F45-G45,0) -> 0 | E45: =IF(E$9="n",F45-G45,0) -> 0 | G45: =IF(($E$11="n"),0,IF((LEFT(C45,1)="v"),F45,IF((LEFT(C45,1)="z"),0,F45*1/6))) -> 0
D46: =IF(E$9="y",F46-G46,0) -> 0 | E46: =IF(E$9="n",F46-G46,0) -> 0 | G46: =IF(($E$11="n"),0,IF((LEFT(C46,1)="v"),F46,IF((LEFT(C46,1)="z"),0,F46*1/6))) -> 0
D47: =IF(E$9="y",F47-G47,0) -> 0 | E47: =IF(E$9="n",F47-G47,0) -> 0 | G47: =IF(($E$11="n"),0,IF((LEFT(C47,1)="v"),F47,IF((LEFT(C47,1)="z"),0,F47*1/6))) -> 0
D48: =IF(E$9="y",F48-G48,0) -> 0 | E48: =IF(E$9="n",F48-G48,0) -> 0 | G48: =IF(($E$11="n"),0,IF((LEFT(C48,1)="v"),F48,IF((LEFT(C48,1)="z"),0,F48*1/6))) -> 0
D49: =IF(E$9="y",F49-G49,0) -> 0 | E49: =IF(E$9="n",F49-G49,0) -> 0 | G49: =IF(($E$11="n"),0,IF((LEFT(C49,1)="v"),F49,IF((LEFT(C49,1)="z"),0,F49*1/6))) -> 0
D50: =IF(E$9="y",F50-G50,0) -> 0 | E50: =IF(E$9="n",F50-G50,0) -> 0 | G50: =IF(($E$11="n"),0,IF((LEFT(C50,1)="v"),F50,IF((LEFT(C50,1)="z"),0,F50*1/6))) -> 0
D51: =IF(E$9="y",F51-G51,0) -> 0 | E51: =IF(E$9="n",F51-G51,0) -> 0 | G51: =IF(($E$11="n"),0,IF((LEFT(C51,1)="v"),F51,IF((LEFT(C51,1)="z"),0,F51*1/6))) -> 0
D52: =IF(E$9="y",F52-G52,0) -> 0 | E52: =IF(E$9="n",F52-G52,0) -> 0 | G52: =IF(($E$11="n"),0,IF((LEFT(C52,1)="v"),F52,IF((LEFT(C52,1)="z"),0,F52*1/6))) -> 0
A53: Total | D53: =SUM(D17:D52) -> 0 | E53: =SUM(E17:E52) -> 11550 | F53: =SUM(F17:F52) -> 13860 | G53: =SUM(G17:G52) -> 2310 | I53: Total | L53: =SUM(L17:L52) -> 13860 | M53: =SUM(M17:M52) -> 0 | N53: =SUM(N17:N52) -> 0 | O53: =SUM(O17:O52) -> 0 | P53: =SUM(P17:P52) -> 2.5
A54: C/fwd | D54: =SUM(D16:D52) -> 0 | E54: =SUM(E16:E52) -> 55000 | F54: =SUM(F16:F52) -> 66000 | G54: =SUM(G16:G52) -> 11000 | I54: C/fwd | L54: =SUM(L16:L52) -> 89100 | M54: =SUM(M16:M52) -> 66.53 | N54: =SUM(N16:N52) -> 0 | O54: =SUM(O16:O52) -> 50488.86 | P54: =SUM(P16:P52) -> -53.82
...

Sheet May 18
A2: ='Nov 17'!A2 -> Design-spectrum Limited
A4: Month | C4: ='Apr 18'!C4+31 -> 43226
A7: Sales Invoices | I7: Bankings - Receipts
A9: Does this months income fall within IR35? (Y/N/both) | E9: ='Apr 18'!E9 -> n | F9: =IF(E9="Both","enter sales invoices manually at row 30 onwards",0) -> 0
A11: Is the Company VAT registered (Y/N) | E11: ='Apr 18'!E11 -> y
A12: VAT Flat rate scheme percentage | E12: ='Apr 18'!E12 -> 0.165
A13: (leave blank or zero if not using flat rate scheme) | M13: Interest | O13: Transfers from | P13: Interest
L14: Sales Invoice | M14: Received on | O14: Deposit | P14: Received on
A15: Date | B15: Details | C15: Sales Invoice No | D15: IR35 | E15: Non IR35 | F15: Gross | G15: VAT | I15: Date | J15: Details | K15: Sales Invoice no | L15: Amount £ | M15: Current Account | N15: Other bankings | O15: Account | P15: Deposit Account
C16: Balance b/f | D16: ='Apr 18'!D54 -> 0 | E16: ='Apr 18'!E54 -> 55000 | F16: ='Apr 18'!F54 -> 66000 | G16: ='Apr 18'!G54 -> 11000 | J16: Balance b/f | L16: ='Apr 18'!L54 -> 89100 | M16: ='Apr 18'!M54 -> 66.53 | N16: ='Apr 18'!N54 -> 0 | O16: ='Apr 18'!O54 -> 50488.86 | P16: ='Apr 18'!P54 -> -53.82
C17: raised next month | D17: =IF(E$9="y",F17-G17,0) -> 0 | E17: =IF(E$9="n",F17-G17,0) -> 0 | G17: =IF(($E$11="n"),0,IF((LEFT(C17,1)="v"),F17,IF((LEFT(C17,1)="z"),0,F17*1/6))) -> 0
D18: =IF(E$9="y",F18-G18,0) -> 0 | E18: =IF(E$9="n",F18-G18,0) -> 0 | G18: =IF(($E$11="n"),0,IF((LEFT(C18,1)="v"),F18,IF((LEFT(C18,1)="z"),0,F18*1/6))) -> 0
D19: =IF(E$9="y",F19-G19,0) -> 0 | E19: =IF(E$9="n",F19-G19,0) -> 0 | G19: =IF(($E$11="n"),0,IF((LEFT(C19,1)="v"),F19,IF((LEFT(C19,1)="z"),0,F19*1/6))) -> 0
D20: =IF(E$9="y",F20-G20,0) -> 0 | E20: =IF(E$9="n",F20-G20,0) -> 0 | G20: =IF(($E$11="n"),0,IF((LEFT(C20,1)="v"),F20,IF((LEFT(C20,1)="z"),0,F20*1/6))) -> 0
D21: =IF(E$9="y",F21-G21,0) -> 0 | E21: =IF(E$9="n",F21-G21,0) -> 0 | G21: =IF(($E$11="n"),0,IF((LEFT(C21,1)="v"),F21,IF((LEFT(C21,1)="z"),0,F21*1/6))) -> 0 | P21: 2.42
D22: =IF(E$9="y",F22-G22,0) -> 0 | E22: =IF(E$9="n",F22-G22,0) -> 0 | G22: =IF(($E$11="n"),0,IF((LEFT(C22,1)="v"),F22,IF((LEFT(C22,1)="z"),0,F22*1/6))) -> 0
D23: =IF(E$9="y",F23-G23,0) -> 0 | E23: =IF(E$9="n",F23-G23,0) -> 0 | G23: =IF(($E$11="n"),0,IF((LEFT(C23,1)="v"),F23,IF((LEFT(C23,1)="z"),0,F23*1/6))) -> 0
D24: =IF(E$9="y",F24-G24,0) -> 0 | E24: =IF(E$9="n",F24-G24,0) -> 0 | G24: =IF(($E$11="n"),0,IF((LEFT(C24,1)="v"),F24,IF((LEFT(C24,1)="z"),0,F24*1/6))) -> 0
D25: =IF(E$9="y",F25-G25,0) -> 0 | E25: =IF(E$9="n",F25-G25,0) -> 0 | G25: =IF(($E$11="n"),0,IF((LEFT(C25,1)="v"),F25,IF((LEFT(C25,1)="z"),0,F25*1/6))) -> 0
D26: =IF(E$9="y",F26-G26,0) -> 0 | E26: =IF(E$9="n",F26-G26,0) -> 0 | G26: =IF(($E$11="n"),0,IF((LEFT(C26,1)="v"),F26,IF((LEFT(C26,1)="z"),0,F26*1/6))) -> 0
D27: =IF(E$9="y",F27-G27,0) -> 0 | E27: =IF(E$9="n",F27-G27,0) -> 0 | G27: =IF(($E$11="n"),0,IF((LEFT(C27,1)="v"),F27,IF((LEFT(C27,1)="z"),0,F27*1/6))) -> 0
D28: =IF(E$9="y",F28-G28,0) -> 0 | E28: =IF(E$9="n",F28-G28,0) -> 0 | G28: =IF(($E$11="n"),0,IF((LEFT(C28,1)="v"),F28,IF((LEFT(C28,1)="z"),0,F28*1/6))) -> 0
D29: =IF(E$9="y",F29-G29,0) -> 0 | E29: =IF(E$9="n",F29-G29,0) -> 0 | G29: =IF(($E$11="n"),0,IF((LEFT(C29,1)="v"),F29,IF((LEFT(C29,1)="z"),0,F29*1/6))) -> 0
D30: =IF(E$9="y",F30-G30,0) -> 0 | E30: =IF(E$9="n",F30-G30,0) -> 0 | G30: =IF(($E$11="n"),0,IF((LEFT(C30,1)="v"),F30,IF((LEFT(C30,1)="z"),0,F30*1/6))) -> 0
D31: =IF(E$9="y",F31-G31,0) -> 0 | E31: =IF(E$9="n",F31-G31,0) -> 0 | G31: =IF(($E$11="n"),0,IF((LEFT(C31,1)="v"),F31,IF((LEFT(C31,1)="z"),0,F31*1/6))) -> 0
D32: =IF(E$9="y",F32-G32,0) -> 0 | E32: =IF(E$9="n",F32-G32,0) -> 0 | G32: =IF(($E$11="n"),0,IF((LEFT(C32,1)="v"),F32,IF((LEFT(C32,1)="z"),0,F32*1/6))) -> 0
D33: =IF(E$9="y",F33-G33,0) -> 0 | E33: =IF(E$9="n",F33-G33,0) -> 0 | G33: =IF(($E$11="n"),0,IF((LEFT(C33,1)="v"),F33,IF((LEFT(C33,1)="z"),0,F33*1/6))) -> 0
... D40: =IF(E$9="y",F40-G40,0) -> 0 | E40: =IF(E$9="n",F40-G40,0) -> 0 | G40: =IF(($E$11="n"),0,IF((LEFT(C40,1)="v"),F40,IF((LEFT(C40,1)="z"),0,F40*1/6))) -> 0
B41: =IF(E9="Both","Enter manual values here",0) -> 0 | D41: =IF(E$9="y",F41-G41,0) -> 0 | E41: =IF(E$9="n",F41-G41,0) -> 0 | G41: =IF(($E$11="n"),0,IF((LEFT(C41,1)="v"),F41,IF((LEFT(C41,1)="z"),0,F41*1/6))) -> 0
D42: =IF(E$9="y",F42-G42,0) -> 0 | E42: =IF(E$9="n",F42-G42,0) -> 0 | G42: =IF(($E$11="n"),0,IF((LEFT(C42,1)="v"),F42,IF((LEFT(C42,1)="z"),0,F42*1/6))) -> 0
D43: =IF(E$9="y",F43-G43,0) -> 0 | E43: =IF(E$9="n",F43-G43,0) -> 0 | G43: =IF(($E$11="n"),0,IF((LEFT(C43,1)="v"),F43,IF((LEFT(C43,1)="z"),0,F43*1/6))) -> 0
D44: =IF(E$9="y",F44-G44,0) -> 0 | E44: =IF(E$9="n",F44-G44,0) -> 0 | G44: =IF(($E$11="n"),0,IF((LEFT(C44,1)="v"),F44,IF((LEFT(C44,1)="z"),0,F44*1/6))) -> 0
D45: =IF(E$9="y",F45-G45,0) -> 0 | E45: =IF(E$9="n",F45-G45,0) -> 0 | G45: =IF(($E$11="n"),0,IF((LEFT(C45,1)="v"),F45,IF((LEFT(C45,1)="z"),0,F45*1/6))) -> 0
D46: =IF(E$9="y",F46-G46,0) -> 0 | E46: =IF(E$9="n",F46-G46,0) -> 0 | G46: =IF(($E$11="n"),0,IF((LEFT(C46,1)="v"),F46,IF((LEFT(C46,1)="z"),0,F46*1/6))) -> 0
D47: =IF(E$9="y",F47-G47,0) -> 0 | E47: =IF(E$9="n",F47-G47,0) -> 0 | G47: =IF(($E$11="n"),0,IF((LEFT(C47,1)="v"),F47,IF((LEFT(C47,1)="z"),0,F47*1/6))) -> 0
D48: =IF(E$9="y",F48-G48,0) -> 0 | E48: =IF(E$9="n",F48-G48,0) -> 0 | G48: =IF(($E$11="n"),0,IF((LEFT(C48,1)="v"),F48,IF((LEFT(C48,1)="z"),0,F48*1/6))) -> 0
D49: =IF(E$9="y",F49-G49,0) -> 0 | E49: =IF(E$9="n",F49-G49,0) -> 0 | G49: =IF(($E$11="n"),0,IF((LEFT(C49,1)="v"),F49,IF((LEFT(C49,1)="z"),0,F49*1/6))) -> 0
D50: =IF(E$9="y",F50-G50,0) -> 0 | E50: =IF(E$9="n",F50-G50,0) -> 0 | G50: =IF(($E$11="n"),0,IF((LEFT(C50,1)="v"),F50,IF((LEFT(C50,1)="z"),0,F50*1/6))) -> 0
D51: =IF(E$9="y",F51-G51,0) -> 0 | E51: =IF(E$9="n",F51-G51,0) -> 0 | G51: =IF(($E$11="n"),0,IF((LEFT(C51,1)="v"),F51,IF((LEFT(C51,1)="z"),0,F51*1/6))) -> 0
D52: =IF(E$9="y",F52-G52,0) -> 0 | E52: =IF(E$9="n",F52-G52,0) -> 0 | G52: =IF(($E$11="n"),0,IF((LEFT(C52,1)="v"),F52,IF((LEFT(C52,1)="z"),0,F52*1/6))) -> 0
...

Sheet Jun 18
A1: 0
A2: ='Nov 17'!A2 -> Design-spectrum Limited
A4: Month | C4: ='May 18'!C4+31 -> 43257
A7: Sales Invoices | I7: Bankings - Receipts
A9: Does this months income fall within IR35? (Y/N/both) | E9: ='May 18'!E9 -> n | F9: =IF(E9="Both","enter sales invoices manually at row 30 onwards",0) -> 0
A11: Is the Company VAT registered (Y/N) | E11: ='May 18'!E11 -> y
A12: VAT Flat rate scheme percentage | E12: ='May 18'!E12 -> 0.165
A13: (leave blank or zero if not using flat rate scheme) | M13: Interest | O13: Transfers from | P13: Interest
L14: Sales Invoice | M14: Received on | O14: Deposit | P14: Received on
A15: Date | B15: Details | C15: Sales Invoice No | D15: IR35 | E15: Non IR35 | F15: Gross | G15: VAT | I15: Date | J15: Details | K15: Sales Invoice no | L15: Amount £ | M15: Current Account | N15: Other bankings | O15: Account | P15: Deposit Account
C16: Balance b/f | D16: ='May 18'!D54 -> 0 | E16: ='May 18'!E54 -> 55000 | F16: ='May 18'!F54 -> 66000 | G16: ='May 18'!G54 -> 11000 | J16: Balance b/f | L16: ='May 18'!L54 -> 89100 | M16: ='May 18'!M54 -> 66.53 | N16: ='May 18'!N54 -> 0 | O16: ='May 18'!O54 -> 50488.86 | P16: ='May 18'!P54 -> -51.4
B17: Invoice 16Apr-08June2018 | D17: =IF(E$9="y",F17-G17,0) -> 0 | E17: =IF(E$9="n",F17-G17,0) -> 20900 | F17: 25080 | G17: =IF(($E$11="n"),0,IF((LEFT(C17,1)="v"),F17,IF((LEFT(C17,1)="z"),0,F17*1/6))) -> 4180 | J17: MONEY MARKET MATURITY | O17: 50555.39
D18: =IF(E$9="y",F18-G18,0) -> 0 | E18: =IF(E$9="n",F18-G18,0) -> 0 | G18: =IF(($E$11="n"),0,IF((LEFT(C18,1)="v"),F18,IF((LEFT(C18,1)="z"),0,F18*1/6))) -> 0 | J18: GROSS INTEREST TO 03JUN2018 FOR ACCOUNT 400290 90709255 | M18: 128.56 | P18: -128.56
D19: =IF(E$9="y",F19-G19,0) -> 0 | E19: =IF(E$9="n",F19-G19,0) -> 0 | G19: =IF(($E$11="n"),0,IF((LEFT(C19,1)="v"),F19,IF((LEFT(C19,1)="z"),0,F19*1/6))) -> 0 | J19: R S C S LTD | L19: 25080
D20: =IF(E$9="y",F20-G20,0) -> 0 | E20: =IF(E$9="n",F20-G20,0) -> 0 | G20: =IF(($E$11="n"),0,IF((LEFT(C20,1)="v"),F20,IF((LEFT(C20,1)="z"),0,F20*1/6))) -> 0 | P20: 2.5
D21: =IF(E$9="y",F21-G21,0) -> 0 | E21: =IF(E$9="n",F21-G21,0) -> 0 | G21: =IF(($E$11="n"),0,IF((LEFT(C21,1)="v"),F21,IF((LEFT(C21,1)="z"),0,F21*1/6))) -> 0
D22: =IF(E$9="y",F22-G22,0) -> 0 | E22: =IF(E$9="n",F22-G22,0) -> 0 | G22: =IF(($E$11="n"),0,IF((LEFT(C22,1)="v"),F22,IF((LEFT(C22,1)="z"),0,F22*1/6))) -> 0
D23: =IF(E$9="y",F23-G23,0) -> 0 | E23: =IF(E$9="n",F23-G23,0) -> 0 | G23: =IF(($E$11="n"),0,IF((LEFT(C23,1)="v"),F23,IF((LEFT(C23,1)="z"),0,F23*1/6))) -> 0
D24: =IF(E$9="y",F24-G24,0) -> 0 | E24: =IF(E$9="n",F24-G24,0) -> 0 | G24: =IF(($E$11="n"),0,IF((LEFT(C24,1)="v"),F24,IF((LEFT(C24,1)="z"),0,F24*1/6))) -> 0
D25: =IF(E$9="y",F25-G25,0) -> 0 | E25: =IF(E$9="n",F25-G25,0) -> 0 | G25: =IF(($E$11="n"),0,IF((LEFT(C25,1)="v"),F25,IF((LEFT(C25,1)="z"),0,F25*1/6))) -> 0
D26: =IF(E$9="y",F26-G26,0) -> 0 | E26: =IF(E$9="n",F26-G26,0) -> 0 | G26: =IF(($E$11="n"),0,IF((LEFT(C26,1)="v"),F26,IF((LEFT(C26,1)="z"),0,F26*1/6))) -> 0
D27: =IF(E$9="y",F27-G27,0) -> 0 | E27: =IF(E$9="n",F27-G27,0) -> 0 | G27: =IF(($E$11="n"),0,IF((LEFT(C27,1)="v"),F27,IF((LEFT(C27,1)="z"),0,F27*1/6))) -> 0
D28: =IF(E$9="y",F28-G28,0) -> 0 | E28: =IF(E$9="n",F28-G28,0) -> 0 | G28: =IF(($E$11="n"),0,IF((LEFT(C28,1)="v"),F28,IF((LEFT(C28,1)="z"),0,F28*1/6))) -> 0
D29: =IF(E$9="y",F29-G29,0) -> 0 | E29: =IF(E$9="n",F29-G29,0) -> 0 | G29: =IF(($E$11="n"),0,IF((LEFT(C29,1)="v"),F29,IF((LEFT(C29,1)="z"),0,F29*1/6))) -> 0
D30: =IF(E$9="y",F30-G30,0) -> 0 | E30: =IF(E$9="n",F30-G30,0) -> 0 | G30: =IF(($E$11="n"),0,IF((LEFT(C30,1)="v"),F30,IF((LEFT(C30,1)="z"),0,F30*1/6))) -> 0
D31: =IF(E$9="y",F31-G31,0) -> 0 | E31: =IF(E$9="n",F31-G31,0) -> 0 | G31: =IF(($E$11="n"),0,IF((LEFT(C31,1)="v"),F31,IF((LEFT(C31,1)="z"),0,F31*1/6))) -> 0
D32: =IF(E$9="y",F32-G32,0) -> 0 | E32: =IF(E$9="n",F32-G32,0) -> 0 | G32: =IF(($E$11="n"),0,IF((LEFT(C32,1)="v"),F32,IF((LEFT(C32,1)="z"),0,F32*1/6))) -> 0
... D40: =IF(E$9="y",F40-G40,0) -> 0 | E40: =IF(E$9="n",F40-G40,0) -> 0 | G40: =IF(($E$11="n"),0,IF((LEFT(C40,1)="v"),F40,IF((LEFT(C40,1)="z"),0,F40*1/6))) -> 0
B41: =IF(E9="Both","Enter manual values here",0) -> 0 | D41: =IF(E$9="y",F41-G41,0) -> 0 | E41: =IF(E$9="n",F41-G41,0) -> 0 | G41: =IF(($E$11="n"),0,IF((LEFT(C41,1)="v"),F41,IF((LEFT(C41,1)="z"),0,F41*1/6))) -> 0
D42: =IF(E$9="y",F42-G42,0) -> 0 | E42: =IF(E$9="n",F42-G42,0) -> 0 | G42: =IF(($E$11="n"),0,IF((LEFT(C42,1)="v"),F42,IF((LEFT(C42,1)="z"),0,F42*1/6))) -> 0
D43: =IF(E$9="y",F43-G43,0) -> 0 | E43: =IF(E$9="n",F43-G43,0) -> 0 | G43: =IF(($E$11="n"),0,IF((LEFT(C43,1)="v"),F43,IF((LEFT(C43,1)="z"),0,F43*1/6))) -> 0
D44: =IF(E$9="y",F44-G44,0) -> 0 | E44: =IF(E$9="n",F44-G44,0) -> 0 | G44: =IF(($E$11="n"),0,IF((LEFT(C44,1)="v"),F44,IF((LEFT(C44,1)="z"),0,F44*1/6))) -> 0
D45: =IF(E$9="y",F45-G45,0) -> 0 | E45: =IF(E$9="n",F45-G45,0) -> 0 | G45: =IF(($E$11="n"),0,IF((LEFT(C45,1)="v"),F45,IF((LEFT(C45,1)="z"),0,F45*1/6))) -> 0
D46: =IF(E$9="y",F46-G46,0) -> 0 | E46: =IF(E$9="n",F46-G46,0) -> 0 | G46: =IF(($E$11="n"),0,IF((LEFT(C46,1)="v"),F46,IF((LEFT(C46,1)="z"),0,F46*1/6))) -> 0
D47: =IF(E$9="y",F47-G47,0) -> 0 | E47: =IF(E$9="n",F47-G47,0) -> 0 | G47: =IF(($E$11="n"),0,IF((LEFT(C47,1)="v"),F47,IF((LEFT(C47,1)="z"),0,F47*1/6))) -> 0
D48: =IF(E$9="y",F48-G48,0) -> 0 | E48: =IF(E$9="n",F48-G48,0) -> 0 | G48: =IF(($E$11="n"),0,IF((LEFT(C48,1)="v"),F48,IF((LEFT(C48,1)="z"),0,F48*1/6))) -> 0
D49: =IF(E$9="y",F49-G49,0) -> 0 | E49: =IF(E$9="n",F49-G49,0) -> 0 | G49: =IF(($E$11="n"),0,IF((LEFT(C49,1)="v"),F49,IF((LEFT(C49,1)="z"),0,F49*1/6))) -> 0
D50: =IF(E$9="y",F50-G50,0) -> 0 | E50: =IF(E$9="n",F50-G50,0) -> 0 | G50: =IF(($E$11="n"),0,IF((LEFT(C50,1)="v"),F50,IF((LEFT(C50,1)="z"),0,F50*1/6))) -> 0
D51: =IF(E$9="y",F51-G51,0) -> 0 | E51: =IF(E$9="n",F51-G51,0) -> 0 | G51: =IF(($E$11="n"),0,IF((LEFT(C51,1)="v"),F51,IF((LEFT(C51,1)="z"),0,F51*1/6))) -> 0
D52: =IF(E$9="y",F52-G52,0) -> 0 | E52: =IF(E$9="n",F52-G52,0) -> 0 | G52: =IF(($E$11="n"),0,IF((LEFT(C52,1)="v"),F52,IF((LEFT(C52,1)="z"),0,F52*1/6))) -> 0
...

Sheet Jul 18
A1: 0
A2: ='Nov 17'!A2 -> Design-spectrum Limited
A4: Month | C4: ='Jun 18'!C4+31 -> 43288
A7: Sales Invoices | I7: Bankings - Receipts
A9: Does this months income fall within IR35? (Y/N/both) | E9: ='Jun 18'!E9 -> n | F9: =IF(E9="Both","enter sales invoices manually at row 30 onwards",0) -> 0
A11: Is the Company VAT registered (Y/N) | E11: ='Jun 18'!E11 -> y
A12: VAT Flat rate scheme percentage | E12: ='Jun 18'!E12 -> 0.165
A13: (leave blank or zero if not using flat rate scheme) | M13: Interest | O13: Transfers from | P13: Interest
L14: Sales Invoice | M14: Received on | O14: Deposit | P14: Received on
A15: Date | B15: Details | C15: Sales Invoice No | D15: IR35 | E15: Non IR35 | F15: Gross | G15: VAT | I15: Date | J15: Details | K15: Sales Invoice no | L15: Amount £ | M15: Current Account | N15: Other bankings | O15: Account | P15: Deposit Account
C16: Balance b/f | D16: ='Jun 18'!D54 -> 0 | E16: ='Jun 18'!E54 -> 75900 | F16: ='Jun 18'!F54 -> 91080 | G16: ='Jun 18'!G54 -> 15180 | J16: Balance b/f | L16: ='Jun 18'!L54 -> 114180 | M16: ='Jun 18'!M54 -> 195.09 | N16: ='Jun 18'!N54 -> 0 | O16: ='Jun 18'!O54 -> 101044.25 | P16: ='Jun 18'!P54 -> -177.46
B17: raised next month | D17: =IF(E$9="y",F17-G17,0) -> 0 | E17: =IF(E$9="n",F17-G17,0) -> 0 | G17: =IF(($E$11="n"),0,IF((LEFT(C17,1)="v"),F17,IF((LEFT(C17,1)="z"),0,F17*1/6))) -> 0 | P17: 2.42
D18: =IF(E$9="y",F18-G18,0) -> 0 | E18: =IF(E$9="n",F18-G18,0) -> 0 | G18: =IF(($E$11="n"),0,IF((LEFT(C18,1)="v"),F18,IF((LEFT(C18,1)="z"),0,F18*1/6))) -> 0
D19: =IF(E$9="y",F19-G19,0) -> 0 | E19: =IF(E$9="n",F19-G19,0) -> 0 | G19: =IF(($E$11="n"),0,IF((LEFT(C19,1)="v"),F19,IF((LEFT(C19,1)="z"),0,F19*1/6))) -> 0
D20: =IF(E$9="y",F20-G20,0) -> 0 | E20: =IF(E$9="n",F20-G20,0) -> 0 | G20: =IF(($E$11="n"),0,IF((LEFT(C20,1)="v"),F20,IF((LEFT(C20,1)="z"),0,F20*1/6))) -> 0
D21: =IF(E$9="y",F21-G21,0) -> 0 | E21: =IF(E$9="n",F21-G21,0) -> 0 | G21: =IF(($E$11="n"),0,IF((LEFT(C21,1)="v"),F21,IF((LEFT(C21,1)="z"),0,F21*1/6))) -> 0
D22: =IF(E$9="y",F22-G22,0) -> 0 | E22: =IF(E$9="n",F22-G22,0) -> 0 | G22: =IF(($E$11="n"),0,IF((LEFT(C22,1)="v"),F22,IF((LEFT(C22,1)="z"),0,F22*1/6))) -> 0
D23: =IF(E$9="y",F23-G23,0) -> 0 | E23: =IF(E$9="n",F23-G23,0) -> 0 | G23: =IF(($E$11="n"),0,IF((LEFT(C23,1)="v"),F23,IF((LEFT(C23,1)="z"),0,F23*1/6))) -> 0
D24: =IF(E$9="y",F24-G24,0) -> 0 | E24: =IF(E$9="n",F24-G24,0) -> 0 | G24: =IF(($E$11="n"),0,IF((LEFT(C24,1)="v"),F24,IF((LEFT(C24,1)="z"),0,F24*1/6))) -> 0
D25: =IF(E$9="y",F25-G25,0) -> 0 | E25: =IF(E$9="n",F25-G25,0) -> 0 | G25: =IF(($E$11="n"),0,IF((LEFT(C25,1)="v"),F25,IF((LEFT(C25,1)="z"),0,F25*1/6))) -> 0
D26: =IF(E$9="y",F26-G26,0) -> 0 | E26: =IF(E$9="n",F26-G26,0) -> 0 | G26: =IF(($E$11="n"),0,IF((LEFT(C26,1)="v"),F26,IF((LEFT(C26,1)="z"),0,F26*1/6))) -> 0
D27: =IF(E$9="y",F27-G27,0) -> 0 | E27: =IF(E$9="n",F27-G27,0) -> 0 | G27: =IF(($E$11="n"),0,IF((LEFT(C27,1)="v"),F27,IF((LEFT(C27,1)="z"),0,F27*1/6))) -> 0
D28: =IF(E$9="y",F28-G28,0) -> 0 | E28: =IF(E$9="n",F28-G28,0) -> 0 | G28: =IF(($E$11="n"),0,IF((LEFT(C28,1)="v"),F28,IF((LEFT(C28,1)="z"),0,F28*1/6))) -> 0
D29: =IF(E$9="y",F29-G29,0) -> 0 | E29: =IF(E$9="n",F29-G29,0) -> 0 | G29: =IF(($E$11="n"),0,IF((LEFT(C29,1)="v"),F29,IF((LEFT(C29,1)="z"),0,F29*1/6))) -> 0
... D40: =IF(E$9="y",F40-G40,0) -> 0 | E40: =IF(E$9="n",F40-G40,0) -> 0 | G40: =IF(($E$11="n"),0,IF((LEFT(C40,1)="v"),F40,IF((LEFT(C40,1)="z"),0,F40*1/6))) -> 0
B41: =IF(E9="Both","Enter manual values here",0) -> 0 | D41: =IF(E$9="y",F41-G41,0) -> 0 | E41: =IF(E$9="n",F41-G41,0) -> 0 | G41: =IF(($E$11="n"),0,IF((LEFT(C41,1)="v"),F41,IF((LEFT(C41,1)="z"),0,F41*1/6))) -> 0
D42: =IF(E$9="y",F42-G42,0) -> 0 | E42: =IF(E$9="n",F42-G42,0) -> 0 | G42: =IF(($E$11="n"),0,IF((LEFT(C42,1)="v"),F42,IF((LEFT(C42,1)="z"),0,F42*1/6))) -> 0
D43: =IF(E$9="y",F43-G43,0) -> 0 | E43: =IF(E$9="n",F43-G43,0) -> 0 | G43: =IF(($E$11="n"),0,IF((LEFT(C43,1)="v"),F43,IF((LEFT(C43,1)="z"),0,F43*1/6))) -> 0
D44: =IF(E$9="y",F44-G44,0) -> 0 | E44: =IF(E$9="n",F44-G44,0) -> 0 | G44: =IF(($E$11="n"),0,IF((LEFT(C44,1)="v"),F44,IF((LEFT(C44,1)="z"),0,F44*1/6))) -> 0
D45: =IF(E$9="y",F45-G45,0) -> 0 | E45: =IF(E$9="n",F45-G45,0) -> 0 | G45: =IF(($E$11="n"),0,IF((LEFT(C45,1)="v"),F45,IF((LEFT(C45,1)="z"),0,F45*1/6))) -> 0
D46: =IF(E$9="y",F46-G46,0) -> 0 | E46: =IF(E$9="n",F46-G46,0) -> 0 | G46: =IF(($E$11="n"),0,IF((LEFT(C46,1)="v"),F46,IF((LEFT(C46,1)="z"),0,F46*1/6))) -> 0
D47: =IF(E$9="y",F47-G47,0) -> 0 | E47: =IF(E$9="n",F47-G47,0) -> 0 | G47: =IF(($E$11="n"),0,IF((LEFT(C47,1)="v"),F47,IF((LEFT(C47,1)="z"),0,F47*1/6))) -> 0
D48: =IF(E$9="y",F48-G48,0) -> 0 | E48: =IF(E$9="n",F48-G48,0) -> 0 | G48: =IF(($E$11="n"),0,IF((LEFT(C48,1)="v"),F48,IF((LEFT(C48,1)="z"),0,F48*1/6))) -> 0
D49: =IF(E$9="y",F49-G49,0) -> 0 | E49: =IF(E$9="n",F49-G49,0) -> 0 | G49: =IF(($E$11="n"),0,IF((LEFT(C49,1)="v"),F49,IF((LEFT(C49,1)="z"),0,F49*1/6))) -> 0
D50: =IF(E$9="y",F50-G50,0) -> 0 | E50: =IF(E$9="n",F50-G50,0) -> 0 | G50: =IF(($E$11="n"),0,IF((LEFT(C50,1)="v"),F50,IF((LEFT(C50,1)="z"),0,F50*1/6))) -> 0
D51: =IF(E$9="y",F51-G51,0) -> 0 | E51: =IF(E$9="n",F51-G51,0) -> 0 | G51: =IF(($E$11="n"),0,IF((LEFT(C51,1)="v"),F51,IF((LEFT(C51,1)="z"),0,F51*1/6))) -> 0
D52: =IF(E$9="y",F52-G52,0) -> 0 | E52: =IF(E$9="n",F52-G52,0) -> 0 | G52: =IF(($E$11="n"),0,IF((LEFT(C52,1)="v"),F52,IF((LEFT(C52,1)="z"),0,F52*1/6))) -> 0
A53: Total | D53: =SUM(D17:D52) -> 0 | E53: =SUM(E17:E52) -> 0 | F53: =SUM(F17:F52) -> 0 | G53: =SUM(G17:G52) -> 0 | I53: Total | L53: =SUM(L17:L52) -> 0 | M53: =SUM(M17:M52) -> 0 | N53: =SUM(N17:N52) -> 0 | O53: =SUM(O17:O52) -> 0 | P53: =SUM(P17:P52) -> 2.42
A54: C/fwd | D54: =SUM(D16:D52) -> 0 | E54: =SUM(E16:E52) -> 75900 | F54: =SUM(F16:F52) -> 91080 | G54: =SUM(G16:G52) -> 15180 | I54: C/fwd | L54: =SUM(L16:L52) -> 114180 | M54: =SUM(M16:M52) -> 195.09 | N54: =SUM(N16:N52) -> 0 | O54: =SUM(O16:O52) -> 101044.25 | P54: =SUM(P16:P52) -> -175.04
A56: IR35 Details (ignore if outside IR35): | D56: Flat Rate Scheme Details (ignore if outside FRS):
...

Sheet Aug 18
A1: 0
A2: ='Nov 17'!A2 -> Design-spectrum Limited
A4: Month | C4: ='Jul 18'!C4+31 -> 43319
A7: Sales Invoices | I7: Bankings - Receipts
A9: Does this months income fall within IR35? (Y/N/both) | E9: ='Jul 18'!E9 -> n | F9: =IF(E9="Both","enter sales invoices manually at row 30 onwards",0) -> 0
A11: Is the Company VAT registered (Y/N) | E11: ='Jul 18'!E11 -> y
A12: VAT Flat rate scheme percentage | E12: ='Jul 18'!E12 -> 0.165
A13: (leave blank or zero if not using flat rate scheme) | M13: Interest | O13: Transfers from | P13: Interest
L14: Sales Invoice | M14: Received on | O14: Deposit | P14: Received on
A15: Date | B15: Details | C15: Sales Invoice No | D15: IR35 | E15: Non IR35 | F15: Gross | G15: VAT | I15: Date | J15: Details | K15: Sales Invoice no | L15: Amount £ | M15: Current Account | N15: Other bankings | O15: Account | P15: Deposit Account
